Workbook
Name solver_opt: Dados_Tese_Completo_Reservatori!$A$1

Sheet Planilha1
A1: RESUMO DOS RESULTADOS
A3: Estatística de regressão
A4: R múltiplo | B4: 0.24012744
A5: R-Quadrado | B5: 0.057661188
A6: R-quadrado ajustado | B6: 0.048989359
A7: Erro padrão | B7: 501.26373
A8: Observações | B8: 330
A10: ANOVA
B11: gl | C11: SQ | D11: MQ | E11: F | F11: F de significação
A12: Regressão | B12: 3 | C12: 5012180.1 | D12: 1670726.7 | E12: 6.6492529 | F12: 0.00022696542
A13: Resíduo | B13: 326 | C13: 81912497 | D13: 251265.33
A14: Total | B14: 329 | C14: 86924677
B16: Coeficientes | C16: Erro padrão | D16: Stat t | E16: valor-P | F16: 95% inferiores | G16: 95% superiores | H16: Inferior 95,0% | I16: Superior 95,0%
A17: Interseção | B17: 5274.7361 | C17: 1685.5262 | D17: 3.1294299 | E17: 0.0019097064 | F17: 1958.8551 | G17: 8590.617 | H17: 1958.8551 | I17: 8590.617
A18: Variável X 1 | B18: -2017.1066 | C18: 638.74472 | D18: -3.1579229 | E18: 0.0017375716 | F18: -3273.6883 | G18: -760.52483 | H18: -3273.6883 | I18: -760.52483
A19: Variável X 2 | B19: -4968.6346 | C19: 1114.7586 | D19: -4.4571394 | E19: 1.1437685e-05 | F19: -7161.6631 | G19: -2775.6062 | H19: -7161.6631 | I19: -2775.6062
A20: Variável X 3 | B20: -0.23579347 | C20: 4.1884732 | D20: -0.056295804 | E20: 0.95514065 | F20: -8.4756408 | G20: 8.0040538 | H20: -8.4756408 | I20: 8.0040538

Sheet Planilha3
A1: RESUMO DOS RESULTADOS
A3: Estatística de regressão
A4: R múltiplo | B4: 0.29691461
A5: R-Quadrado | B5: 0.088158285
A6: R-quadrado ajustado | B6: 0.074086654
A7: Erro padrão | B7: 459.70474
A8: Observações | B8: 330
A10: ANOVA
B11: gl | C11: SQ | D11: MQ | E11: F | F11: F de significação
A12: Regressão | B12: 5 | C12: 6619827.1 | D12: 1323965.4 | E12: 6.2649655 | F12: 1.4492061e-05
A13: Resíduo | B13: 324 | C13: 68470416 | D13: 211328.44
A14: Total | B14: 329 | C14: 75090243
B16: Coeficientes | C16: Erro padrão | D16: Stat t | E16: valor-P | F16: 95% inferiores | G16: 95% superiores | H16: Inferior 95,0% | I16: Superior 95,0%
A17: Interseção | B17: -1564.3227 | C17: 2245.5949 | D17: -0.69661838 | E17: 0.48654112 | F17: -5982.1103 | G17: 2853.4649 | H17: -5982.1103 | I17: 2853.4649
A18: Variável X 1 | B18: -17.952875 | C18: 874.61019 | D18: -0.020526716 | E18: 0.98363584 | F18: -1738.5847 | G18: 1702.6789 | H18: -1738.5847 | I18: 1702.6789
A19: Variável X 2 | B19: -1583.4843 | C19: 1198.7469 | D19: -1.3209496 | E19: 0.18745035 | F19: -3941.7945 | G19: 774.82587 | H19: -3941.7945 | I19: 774.82587
A20: Variável X 3 | B20: 5.0151242 | C20: 4.0450077 | D20: 1.2398306 | E20: 0.21593528 | F20: -2.9426711 | G20: 12.97292 | H20: -2.9426711 | I20: 12.97292
A21: Variável X 4 | B21: 0.18814822 | C21: 0.11526454 | D21: 1.6323166 | E21: 0.10358427 | F21: -0.038613177 | G21: 0.41490961 | H21: -0.038613177 | I21: 0.41490961
A22: Variável X 5 | B22: 0.22182941 | C22: 0.056164974 | D22: 3.9496041 | E22: 9.6086774e-05 | F22: 0.11133534 | G22: 0.33232348 | H22: 0.11133534 | I22: 0.33232348

Sheet Planilha4
A1: RESUMO DOS RESULTADOS
A3: Estatística de regressão
A4: R múltiplo | B4: 0.21003778
A5: R-Quadrado | B5: 0.044115869
A6: R-quadrado ajustado | B6: 0.038269483
A7: Erro padrão | B7: 468.51177
A8: Observações | B8: 330
A10: ANOVA
B11: gl | C11: SQ | D11: MQ | E11: F | F11: F de significação
A12: Regressão | B12: 2 | C12: 3312671.3 | D12: 1656335.7 | E12: 7.5458356 | F12: 0.00062554518
A13: Resíduo | B13: 327 | C13: 71777572 | D13: 219503.28
A14: Total | B14: 329 | C14: 75090243
B16: Coeficientes | C16: Erro padrão | D16: Stat t | E16: valor-P | F16: 95% inferiores | G16: 95% superiores | H16: Inferior 95,0% | I16: Superior 95,0%
A17: Interseção | B17: 3848.5413 | C17: 1469.5702 | D17: 2.6188209 | E17: 0.0092342981 | F17: 957.53646 | G17: 6739.5462 | H17: 957.53646 | I17: 6739.5462
A18: Variável X 1 | B18: -1523.4392 | C18: 530.42715 | D18: -2.8720989 | E18: 0.0043437921 | F18: -2566.9195 | G18: -479.95903 | H18: -2566.9195 | I18: -479.95903
A19: Variável X 2 | B19: -4028.3226 | C19: 1040.6375 | D19: -3.8710142 | E19: 0.00013086735 | F19: -6075.5117 | G19: -1981.1336 | H19: -6075.5117 | I19: -1981.1336

Sheet Planilha5
A1: RESUMO DOS RESULTADOS
A3: Estatística de regressão
A4: R múltiplo | B4: 0.97183356
A5: R-Quadrado | B5: 0.94446046
A6: R-quadrado ajustado | B6: 0.9437769
A7: Erro padrão | B7: 121.8796
A8: Observações | B8: 330
A10: ANOVA
B11: gl | C11: SQ | D11: MQ | E11: F | F11: F de significação
A12: Regressão | B12: 4 | C12: 82096920 | D12: 20524230 | E12: 1381.6717 | F12: 1.537196e-202
A13: Resíduo | B13: 325 | C13: 4827756.7 | D13: 14854.636
A14: Total | B14: 329 | C14: 86924677
B16: Coeficientes | C16: Erro padrão | D16: Stat t | E16: valor-P | F16: 95% inferiores | G16: 95% superiores | H16: Inferior 95,0% | I16: Superior 95,0%
A17: Interseção | B17: 1184.4195 | C17: 413.74147 | D17: 2.8627043 | E17: 0.0044730699 | F17: 370.47001 | G17: 1998.369 | H17: 370.47001 | I17: 1998.369
A18: Variável X 1 | B18: -391.10556 | C18: 156.93905 | D18: -2.4920856 | E18: 0.013197396 | F18: -699.8502 | G18: -82.360916 | H18: -699.8502 | I18: -82.360916
A19: Variável X 2 | B19: -789.64008 | C19: 277.18623 | D19: -2.848771 | E19: 0.004668626 | F19: -1334.9458 | G19: -244.33436 | H19: -1334.9458 | I19: -244.33436
A20: Variável X 3 | B20: -0.97923124 | C20: 1.0184572 | D20: -0.96148496 | E20: 0.33702317 | F20: -2.9828319 | G20: 1.0243694 | H20: -2.9828319 | I20: 1.0243694
A21: Variável X 4 | B21: 1.0292005 | C21: 0.014287189 | D21: 72.036599 | E21: 7.046822e-202 | F21: 1.0010934 | G21: 1.0573075 | H21: 1.0010934 | I21: 1.0573075

Sheet Dados_Tese_Completo_Reservatori
A1: %Well | B1: : | C1: 3-BRSA-1132-RJS | D1: : | E1: 43133 | F1: 0.58302083
A2: %DEPTH | B2: AO10 | C2: AO20 | D2: AO30 | E2: AO60 | F2: AO90 | G2: AORT | H2: AORX | K2: n | L2: AT(10/20/30) Paral | M2: AT10 | N2: AT20 | O2: AT30 | P2: AT60 | Q2: AT90 | R2: _DEN | S2: _NEU | T2: _GR | U2: Totuosity | V2: _VP | X2: AT10 | Y2: _VS | Z2: Phi | AA2: k | AB2: previsão | AC2: nmrT2M | AD2: SW | AE2: SWU | AF2: SXO | AG2: SXOU | AH2: Totuosity | AJ2: AORT/AO90 | AL2: AORT/AORX | AM2: Di | AQ2: Phi% | AR2: Phi | AS2: Phi Frac | AT2: Phi Horiz | AU2: Phi Vert | AV2: Fracture Dipping | AW2: Index Resisty | AX2: Angle | BA2: Porosidade total
A3: %M | B3: ohm,m | C3: ohm,m | D3: ohm,m | E3: ohm,m | F3: ohm,m | G3: ohm,m | H3: ohm,m | J3: Index | M3: ohm,m | N3: ohm,m | O3: ohm,m | P3: ohm,m | Q3: ohm,m | R3: G/CC | S3: V/V | T3: API | V3: M/S | X3: ohm,m | Y3: M/S | Z3: V/V | AA3: % | AC3: ms | AD3: Dec | AE3: Dec | AF3: Dec | AG3: Dec | AR3: V/V
W4: coef | AN4: R_ABGH
A5: 5574.9825 | B5: 272.2705 | C5: 302.0356 | D5: 413.7392 | E5: 292.4842 | F5: 271.66 | G5: 291.7903 | H5: 221.9146 | I5: =(1/(1/B5)+(1/M5)+(1/C5)+(1/N5)) -> 272.2811 | J5: =G5/145.9555 -> 1.999173 | K5: =-LOG(AD5)-LOG(J5) -> 0.86791992 | L5: =(M5+N5+O5+B5+C5+D5)/6 -> 314.85273 | M5: 268.7348 | N5: 280.5922 | O5: 351.7441 | P5: 295.2119 | Q5: 236.6486 | R5: 2.4184 | S5: 0.2363 | T5: 19.5545 | U5: 3.7442 | V5: 4142.1187 | W5: 1184.4195 | X5: 268.7348 | Y5: 2234.7693 | Z5: 0.192 | AA5: 135 | AB5: =W5+$W$6*R5+$W$7*S5+$W$8*T5+$W$9*U5 -> 36.683017 | AC5: 476.3855 | AD5: 0.0678 | AE5: 0.0678 | AF5: 0.0676 | AG5: 0.0653 | AH5: 3.7442 | AI5: =Z5^(1-1.89) -> 4.3437208 | AJ5: =G5/H5 -> 1.3148765 | AK5: =ABS(AJ5-1) -> 0.31487653 | AL5: =F5/B5 -> 0.99775774 | AM5: =ABS(AL5-1) -> 0.0022422554 | AO5: =((B5+Q5)/2)*(Z5^3)/((1-Z5)^2) -> 2.7586698 | AP5: =Z5*AD5 -> 0.0130176 | AQ5: =AR5/100 -> 0.00192 | AR5: 0.192 | AS5: 0.229 | AT5: =(H5*Q5)*((1/Q5^2)-(1/I5^2)) -> 0.22937759 | AU5: =(2*H5*Q5)*((1/I5^2)-(1/Q5^2)) -> -0.45875519 | AV5: =(F5-H5)/((F5*H5)^0.5) -> 0.20260359 | AW5: =Q5/H5 -> 1.0663949 | AX5: =((TAN(DEGREES(AV5)))) -> -1.4224149 | AY5: =IF(AV5>0.1,"SUB-VERTICAL",IF(AV5<0,"SUB-HORIZONTAL","MERGULHO")) -> SUB-VERTICAL | AZ5: =IF(AV5>0.1,"1",IF(AV5<0,"2","3")) -> 1 | BA5: =(R5+S5)/2 -> 1.32735 | BB5: =ATAN(0.2) -> 0.19739556
A6: 5575.0587 | B6: 244.2342 | C6: 258.602 | D6: 337.6454 | E6: 267.3022 | F6: 249.0079 | G6: 263.5609 | H6: 200.8569 | I6: =(1/(1/B6)+(1/M6)+(1/C6)+(1/N6)) -> 244.24642 | J6: =G6/145.9555 -> 1.805762 | K6: =-LOG(AD6)-LOG(J6) -> 0.91210979 | L6: =(M6+N6+O6+B6+C6+D6)/6 -> 270.76007 | M6: 231.4431 | N6: 247.774 | O6: 304.8617 | P6: 260.045 | Q6: 219.3672 | R6: 2.4184 | S6: 0.2363 | T6: 19.5545 | U6: 3.7442 | V6: 4142.1187 | W6: -391.10556 | X6: 231.4431 | Y6: 2234.7693 | Z6: 0.192 | AA6: 135 | AB6: =W6+$W$6*R6+$W$7*S6+$W$8*T6+$W$9*U6 -> -1538.842 | AC6: 476.3855 | AD6: 0.0678 | AE6: 0.0678 | AF6: 0.0676 | AG6: 0.0653 | AH6: 3.7442 | AI6: =Z6^(1-1.89) -> 4.3437208 | AJ6: =G6/H6 -> 1.3121825 | AK6: =ABS(AJ6-1) -> 0.31218245 | AL6: =F6/B6 -> 1.0195456 | AM6: =ABS(AL6-1) -> 0.019545584 | AO6: =((B6+Q6)/2)*(Z6^3)/((1-Z6)^2) -> 2.5130186 | AP6: =Z6*AD6 -> 0.0130176 | AQ6: =AR6/100 -> 0.00192 | AR6: 0.192 | AS6: 0.177 | AT6: =(H6*Q6)*((1/Q6^2)-(1/I6^2)) -> 0.17703195 | AU6: =(2*H6*Q6)*((1/I6^2)-(1/Q6^2)) -> -0.3540639 | AV6: =(F6-H6)/((F6*H6)^0.5) -> 0.21530562 | AW6: =Q6/H6 -> 1.0921567 | AX6: =((ATAN(AV6)))*3.14 -> 0.66589434 | AY6: =IF(AV6>0.1,"SUB-VERTICAL",IF(AV6<0,"SUB-HORIZONTAL","MERGULHO")) -> SUB-VERTICAL | AZ6: =IF(AV6>0.1,"1",IF(AV6<0,"2","3")) -> 1 | BA6: =(R6+S6)/2 -> 1.32735
A7: 5575.1349 | B7: 198.2799 | C7: 216.3792 | D7: 269.1673 | E7: 231.3244 | F7: 216.5693 | G7: 230.409 | H7: 181.7894 | I7: =(1/(1/B7)+(1/M7)+(1/C7)+(1/N7)) -> 198.29394 | J7: =G7/145.9555 -> 1.578625 | K7: =-LOG(AD7)-LOG(J7) -> 0.93543369 | L7: =(M7+N7+O7+B7+C7+D7)/6 -> 229.27115 | M7: 207.2651 | N7: 217.7824 | O7: 266.753 | P7: 233.8474 | Q7: 208.9197 | R7: 2.4231 | S7: 0.2303 | T7: 21.2915 | U7: -999 | V7: 4213.8423 | W7: -789.64008 | X7: 207.2651 | Y7: 2273.2729 | Z7: -999 | AA7: -999 | AB7: =W7+$W$6*R7+$W$7*S7+$W$8*T7+$W$9*U7 -> -2968.2027 | AC7: 460.9184 | AD7: 0.0735 | AE7: 0.0735 | AF7: 0.0749 | AG7: 0.0747 | AH7: -999 | AI7: =Z7^(1-1.89) -> #NUM! | AJ7: =G7/H7 -> 1.2674501 | AK7: =ABS(AJ7-1) -> 0.26745014 | AL7: =F7/B7 -> 1.0922403 | AM7: =ABS(AL7-1) -> 0.092240313 | AO7: =((B7+Q7)/2)*(Z7^3)/((1-Z7)^2) -> -202989.61 | AP7: =Z7*AD7 -> -73.4265 | AQ7: =AR7/100 -> -9.99 | AR7: -999 | AT7: =(H7*Q7)*((1/Q7^2)-(1/I7^2)) -> -0.095753065 | AU7: =(2*H7*Q7)*((1/I7^2)-(1/Q7^2)) -> 0.19150613 | AV7: =(F7-H7)/((F7*H7)^0.5) -> 0.17528534 | AW7: =Q7/H7 -> 1.1492403 | AX7: =((ATAN(AV7))^(-1))*3.14 -> 18.095634 | AY7: =IF(AV7>0.1,"SUB-VERTICAL",IF(AV7<0,"SUB-HORIZONTAL","MERGULHO")) -> SUB-VERTICAL | AZ7: =IF(AV7>0.1,"1",IF(AV7<0,"2","3")) -> 1 | BA7: =(R7+S7)/2 -> 1.3267
A8: 5575.2111 | B8: 161.8855 | C8: 185.2102 | D8: 230.8411 | E8: 214.3378 | F8: 201.1833 | G8: 214.9433 | H8: 169.652 | I8: =(1/(1/B8)+(1/M8)+(1/C8)+(1/N8)) -> 161.90127 | J8: =G8/145.9555 -> 1.4726632 | K8: =-LOG(AD8)-LOG(J8) -> 0.96560921 | L8: =(M8+N8+O8+B8+C8+D8)/6 -> 200.07913 | M8: 190.3048 | N8: 195.2725 | O8: 236.9607 | P8: 215.2252 | Q8: 199.0216 | R8: 2.4231 | S8: 0.2303 | T8: 21.2915 | U8: -999 | V8: 4213.8423 | W8: -0.97923124 | X8: 190.3048 | Y8: 2273.2729 | Z8: -999 | AA8: -999 | AB8: =W8+$W$6*R8+$W$7*S8+$W$8*T8+$W$9*U8 -> -2179.5418 | AC8: 460.9184 | AD8: 0.0735 | AE8: 0.0735 | AF8: 0.0749 | AG8: 0.0747 | AH8: -999 | AI8: =Z8^(1-1.89) -> #NUM! | AJ8: =G8/H8 -> 1.2669659 | AK8: =ABS(AJ8-1) -> 0.26696591 | AL8: =F8/B8 -> 1.2427506 | AM8: =ABS(AL8-1) -> 0.24275059 | AO8: =((B8+Q8)/2)*(Z8^3)/((1-Z8)^2) -> -179912.73 | AP8: =Z8*AD8 -> -73.4265 | AQ8: =AR8/100 -> -9.99 | AR8: -999 | AT8: =(H8*Q8)*((1/Q8^2)-(1/I8^2)) -> -0.43569684 | AU8: =(2*H8*Q8)*((1/I8^2)-(1/Q8^2)) -> 0.87139368 | AV8: =(F8-H8)/((F8*H8)^0.5) -> 0.17067363 | AW8: =Q8/H8 -> 1.1731167 | AX8: =((ATAN(AV8))^(-1))*3.14 -> 18.574959 | AY8: =IF(AV8>0.1,"SUB-VERTICAL",IF(AV8<0,"SUB-HORIZONTAL","MERGULHO")) -> SUB-VERTICAL | AZ8: =IF(AV8>0.1,"1",IF(AV8<0,"2","3")) -> 1 | BA8: =(R8+S8)/2 -> 1.3267
A9: 5575.2873 | B9: 154.5627 | C9: 175.0008 | D9: 217.0409 | E9: 205.246 | F9: 192.7874 | G9: 204.9922 | H9: 158.5866 | I9: =(1/(1/B9)+(1/M9)+(1/C9)+(1/N9)) -> 154.57971 | J9: =G9/145.9555 -> 1.4044842 | K9: =-LOG(AD9)-LOG(J9) -> 0.93708329 | L9: =(M9+N9+O9+B9+C9+D9)/6 -> 185.9222 | M9: 174.3644 | N9: 179.9694 | O9: 214.595 | P9: 199.6656 | Q9: 189.3034 | R9: 2.4354 | S9: 0.2182 | T9: 22.1467 | U9: -999 | V9: 4238.5474 | W9: 1.0292005 | X9: 174.3644 | Y9: 2330.9636 | Z9: -999 | AA9: -999 | AB9: =W9+$W$6*R9+$W$7*S9+$W$8*T9+$W$9*U9 -> -2173.6268 | AC9: -999 | AD9: 0.0823 | AE9: 0.0823 | AF9: 0.0866 | AG9: 0.0866 | AH9: -999 | AI9: =Z9^(1-1.89) -> #NUM! | AJ9: =G9/H9 -> 1.2926199 | AK9: =ABS(AJ9-1) -> 0.29261993 | AL9: =F9/B9 -> 1.2473087 | AM9: =ABS(AL9-1) -> 0.2473087 | AO9: =((B9+Q9)/2)*(Z9^3)/((1-Z9)^2) -> -171417.77 | AP9: =Z9*AD9 -> -82.2177 | AQ9: =AR9/100 -> -9.99 | AR9: -999 | AT9: =(H9*Q9)*((1/Q9^2)-(1/I9^2)) -> -0.41863919 | AU9: =(2*H9*Q9)*((1/I9^2)-(1/Q9^2)) -> 0.83727838 | AV9: =(F9-H9)/((F9*H9)^0.5) -> 0.19559768 | AW9: =Q9/H9 -> 1.193691 | AX9: =((ATAN(AV9))^(-1))*3.14 -> 16.256038 | AY9: =IF(AV9>0.1,"SUB-VERTICAL",IF(AV9<0,"SUB-HORIZONTAL","MERGULHO")) -> SUB-VERTICAL | AZ9: =IF(AV9>0.1,"1",IF(AV9<0,"2","3")) -> 1 | BA9: =(R9+S9)/2 -> 1.3268
A10: 5575.3635 | B10: 147.7557 | C10: 179.7718 | D10: 213.0172 | E10: 199.9811 | F10: 188.4116 | G10: 199.6382 | H10: 143.0686 | I10: =(1/(1/B10)+(1/M10)+(1/C10)+(1/N10)) -> 147.77346 | J10: =G10/145.9555 -> 1.3678018 | K10: =-LOG(AD10)-LOG(J10) -> 0.94857698 | L10: =(M10+N10+O10+B10+C10+D10)/6 -> 177.53567 | M10: 160.7515 | N10: 167.3019 | O10: 196.6159 | P10: 187.4789 | Q10: 180.4017 | R10: 2.4354 | S10: 0.2182 | T10: 22.1467 | U10: -999 | V10: 4238.5474 | X10: 160.7515 | Y10: 2330.9636 | Z10: -999 | AA10: -999 | AB10: =W10+$W$6*R10+$W$7*S10+$W$8*T10+$W$9*U10 -> -2174.656 | AC10: -999 | AD10: 0.0823 | AE10: 0.0823 | AF10: 0.0866 | AG10: 0.0866 | AH10: -999 | AI10: =Z10^(1-1.89) -> #NUM! | AJ10: =G10/H10 -> 1.3954019 | AK10: =ABS(AJ10-1) -> 0.39540193 | AL10: =F10/B10 -> 1.2751562 | AM10: =ABS(AL10-1) -> 0.27515622 | AO10: =((B10+Q10)/2)*(Z10^3)/((1-Z10)^2) -> -163586.96 | AP10: =Z10*AD10 -> -82.2177 | AQ10: =AR10/100 -> -9.99 | AR10: -999 | AT10: =(H10*Q10)*((1/Q10^2)-(1/I10^2)) -> -0.38887512 | AU10: =(2*H10*Q10)*((1/I10^2)-(1/Q10^2)) -> 0.77775024 | AV10: =(F10-H10)/((F10*H10)^0.5) -> 0.27617494 | AW10: =Q10/H10 -> 1.2609454 | AX10: =((ATAN(AV10))^(-1))*3.14 -> 11.653013 | AY10: =IF(AV10>0.1,"SUB-VERTICAL",IF(AV10<0,"SUB-HORIZONTAL","MERGULHO")) -> SUB-VERTICAL | AZ10: =IF(AV10>0.1,"1",IF(AV10<0,"2","3")) -> 1 | BA10: =(R10+S10)/2 -> 1.3268
A11: 5575.4397 | B11: 148.0392 | C11: 169.9331 | D11: 198.7945 | E11: 189.3501 | F11: 178.8564 | G11: 188.6397 | H11: 134.8949 | I11: =(1/(1/B11)+(1/M11)+(1/C11)+(1/N11)) -> 148.05822 | J11: =G11/145.9555 -> 1.2924467 | K11: =-LOG(AD11)-LOG(J11) -> 0.93050152 | L11: =(M11+N11+O11+B11+C11+D11)/6 -> 166.8078 | M11: 149.7859 | N11: 154.8459 | O11: 179.4482 | P11: 177.8641 | Q11: 173.0512 | R11: 2.4499 | S11: 0.2087 | T11: 22.8113 | U11: -999 | V11: 4211.5977 | X11: 149.7859 | Y11: 2357.5288 | Z11: -999 | AA11: -999 | AB11: =W11+$W$6*R11+$W$7*S11+$W$8*T11+$W$9*U11 -> -2173.4762 | AC11: 457.4338 | AD11: 0.0908 | AE11: 0.0908 | AF11: 0.0972 | AG11: 0.0972 | AH11: -999 | AI11: =Z11^(1-1.89) -> #NUM! | AJ11: =G11/H11 -> 1.3984198 | AK11: =ABS(AJ11-1) -> 0.39841981 | AL11: =F11/B11 -> 1.2081692 | AM11: =ABS(AL11-1) -> 0.20816919 | AO11: =((B11+Q11)/2)*(Z11^3)/((1-Z11)^2) -> -160064.05 | AP11: =Z11*AD11 -> -90.7092 | AQ11: =AR11/100 -> -9.99 | AR11: -999 | AT11: =(H11*Q11)*((1/Q11^2)-(1/I11^2)) -> -0.28538226 | AU11: =(2*H11*Q11)*((1/I11^2)-(1/Q11^2)) -> 0.57076453 | AV11: =(F11-H11)/((F11*H11)^0.5) -> 0.2830235 | AW11: =Q11/H11 -> 1.2828595 | AX11: =((ATAN(AV11))^(-1))*3.14 -> 11.384641 | AY11: =IF(AV11>0.1,"SUB-VERTICAL",IF(AV11<0,"SUB-HORIZONTAL","MERGULHO")) -> SUB-VERTICAL | AZ11: =IF(AV11>0.1,"1",IF(AV11<0,"2","3")) -> 1 | BA11: =(R11+S11)/2 -> 1.3293
A12: 5575.5159 | B12: 149.4117 | C12: 145.5879 | D12: 171.2837 | E12: 171.9228 | F12: 162.9519 | G12: 170.4498 | H12: 125.2556 | I12: =(1/(1/B12)+(1/M12)+(1/C12)+(1/N12)) -> 149.4322 | J12: =G12/145.9555 -> 1.1678203 | K12: =-LOG(AD12)-LOG(J12) -> 0.97453812 | L12: =(M12+N12+O12+B12+C12+D12)/6 -> 154.52585 | M12: 146.2072 | N12: 147.2162 | O12: 167.4484 | P12: 169.7591 | Q12: 169.1587 | R12: 2.4499 | S12: 0.2087 | T12: 22.8113 | U12: -999 | V12: 4211.5977 | X12: 146.2072 | Y12: 2357.5288 | Z12: -999 | AA12: -999 | AB12: =W12+$W$6*R12+$W$7*S12+$W$8*T12+$W$9*U12 -> -2173.4762 | AC12: 457.4338 | AD12: 0.0908 | AE12: 0.0908 | AF12: 0.0972 | AG12: 0.0972 | AH12: -999 | AI12: =Z12^(1-1.89) -> #NUM! | AJ12: =G12/H12 -> 1.3608158 | AK12: =ABS(AJ12-1) -> 0.3608158 | AL12: =F12/B12 -> 1.0906234 | AM12: =ABS(AL12-1) -> 0.090623425 | AO12: =((B12+Q12)/2)*(Z12^3)/((1-Z12)^2) -> -158807.82 | AP12: =Z12*AD12 -> -90.7092 | AQ12: =AR12/100 -> -9.99 | AR12: -999 | AT12: =(H12*Q12)*((1/Q12^2)-(1/I12^2)) -> -0.20840004 | AU12: =(2*H12*Q12)*((1/I12^2)-(1/Q12^2)) -> 0.41680009 | AV12: =(F12-H12)/((F12*H12)^0.5) -> 0.2638581 | AW12: =Q12/H12 -> 1.3505081 | AX12: =((ATAN(AV12))^(-1))*3.14 -> 12.171559 | AY12: =IF(AV12>0.1,"SUB-VERTICAL",IF(AV12<0,"SUB-HORIZONTAL","MERGULHO")) -> SUB-VERTICAL | AZ12: =IF(AV12>0.1,"1",IF(AV12<0,"2","3")) -> 1 | BA12: =(R12+S12)/2 -> 1.3293
A13: 5575.5921 | B13: 144.7914 | C13: 130.0799 | D13: 149.3136 | E13: 147.3416 | F13: 140.3855 | G13: 146.8832 | H13: 121.2716 | I13: =(1/(1/B13)+(1/M13)+(1/C13)+(1/N13)) -> 144.81326 | J13: =G13/145.9555 -> 1.006356 | K13: =-LOG(AD13)-LOG(J13) -> 0.99206783 | L13: =(M13+N13+O13+B13+C13+D13)/6 -> 144.36688 | M13: 140.3365 | N13: 141.9851 | O13: 159.6948 | P13: 161.3797 | Q13: 163.9201 | R13: 2.4596 | S13: 0.2081 | T13: 23.6319 | U13: -999 | V13: 4254.793 | X13: 140.3365 | Y13: 2361.2354 | Z13: -999 | AA13: -999 | AB13: =W13+$W$6*R13+$W$7*S13+$W$8*T13+$W$9*U13 -> -2177.5997 | AC13: 422.6129 | AD13: 0.1012 | AE13: 0.1012 | AF13: 0.1034 | AG13: 0.1034 | AH13: -999 | AI13: =Z13^(1-1.89) -> #NUM! | AJ13: =G13/H13 -> 1.2111921 | AK13: =ABS(AJ13-1) -> 0.21119207 | AL13: =F13/B13 -> 0.96957071 | AM13: =ABS(AL13-1) -> 0.030429293 | AO13: =((B13+Q13)/2)*(Z13^3)/((1-Z13)^2) -> -153893.15 | AP13: =Z13*AD13 -> -101.0988 | AQ13: =AR13/100 -> -9.99 | AR13: -999 | AT13: =(H13*Q13)*((1/Q13^2)-(1/I13^2)) -> -0.20810512 | AU13: =(2*H13*Q13)*((1/I13^2)-(1/Q13^2)) -> 0.41621024 | AV13: =(F13-H13)/((F13*H13)^0.5) -> 0.14649022 | AW13: =Q13/H13 -> 1.3516776 | AX13: =((ATAN(AV13))^(-1))*3.14 -> 21.587337 | AY13: =IF(AV13>0.1,"SUB-VERTICAL",IF(AV13<0,"SUB-HORIZONTAL","MERGULHO")) -> SUB-VERTICAL | AZ13: =IF(AV13>0.1,"1",IF(AV13<0,"2","3")) -> 1 | BA13: =(R13+S13)/2 -> 1.33385
A14: 5575.6683 | B14: 141.9917 | C14: 126.1878 | D14: 141.1382 | E14: 133.764 | F14: 127.9555 | G14: 134.0241 | H14: 113.7666 | I14: =(1/(1/B14)+(1/M14)+(1/C14)+(1/N14)) -> 142.01441 | J14: =G14/145.9555 -> 0.91825317 | K14: =-LOG(AD14)-LOG(J14) -> 1.0318571 | L14: =(M14+N14+O14+B14+C14+D14)/6 -> 138.8692 | M14: 133.6108 | N14: 136.9606 | O14: 153.3261 | P14: 152.7753 | Q14: 156.2171 | R14: 2.4596 | S14: 0.2081 | T14: 23.6319 | U14: -999 | V14: 4254.793 | X14: 133.6108 | Y14: 2361.2354 | Z14: -999 | AA14: -999 | AB14: =W14+$W$6*R14+$W$7*S14+$W$8*T14+$W$9*U14 -> -2177.5997 | AC14: 422.6129 | AD14: 0.1012 | AE14: 0.1012 | AF14: 0.1034 | AG14: 0.1034 | AH14: -999 | AI14: =Z14^(1-1.89) -> #NUM! | AJ14: =G14/H14 -> 1.1780619 | AK14: =ABS(AJ14-1) -> 0.17806193 | AL14: =F14/B14 -> 0.90114774 | AM14: =ABS(AL14-1) -> 0.098852257 | AO14: =((B14+Q14)/2)*(Z14^3)/((1-Z14)^2) -> -148657.53 | AP14: =Z14*AD14 -> -101.0988 | AQ14: =AR14/100 -> -9.99 | AR14: -999 | AT14: =(H14*Q14)*((1/Q14^2)-(1/I14^2)) -> -0.1529486 | AU14: =(2*H14*Q14)*((1/I14^2)-(1/Q14^2)) -> 0.30589719 | AV14: =(F14-H14)/((F14*H14)^0.5) -> 0.11760123 | AW14: =Q14/H14 -> 1.3731368 | AX14: =((ATAN(AV14))^(-1))*3.14 -> 26.82304 | AY14: =IF(AV14>0.1,"SUB-VERTICAL",IF(AV14<0,"SUB-HORIZONTAL","MERGULHO")) -> SUB-VERTICAL | AZ14: =IF(AV14>0.1,"1",IF(AV14<0,"2","3")) -> 1 | BA14: =(R14+S14)/2 -> 1.33385
A15: 5575.7445 | B15: 135.0677 | C15: 130.6984 | D15: 145.8697 | E15: 142.1967 | F15: 136.1207 | G15: 142.3432 | H15: 103.9366 | I15: =(1/(1/B15)+(1/M15)+(1/C15)+(1/N15)) -> 135.0907 | J15: =G15/145.9555 -> 0.97525068 | K15: =-LOG(AD15)-LOG(J15) -> 0.98969444 | L15: =(M15+N15+O15+B15+C15+D15)/6 -> 136.80843 | M15: 128.2201 | N15: 132.4579 | O15: 148.5368 | P15: 144.2426 | Q15: 149.3035 | R15: 2.464 | S15: 0.2121 | T15: 25.5975 | U15: -999 | V15: 4351.2993 | X15: 128.2201 | Y15: 2367.2405 | Z15: -999 | AA15: -999 | AB15: =W15+$W$6*R15+$W$7*S15+$W$8*T15+$W$9*U15 -> -2184.4039 | AC15: 443.7227 | AD15: 0.105 | AE15: 0.105 | AF15: 0.1069 | AG15: 0.1069 | AH15: -999 | AI15: =Z15^(1-1.89) -> #NUM! | AJ15: =G15/H15 -> 1.3695195 | AK15: =ABS(AJ15-1) -> 0.3695195 | AL15: =F15/B15 -> 1.0077961 | AM15: =ABS(AL15-1) -> 0.0077960904 | AO15: =((B15+Q15)/2)*(Z15^3)/((1-Z15)^2) -> -141759.47 | AP15: =Z15*AD15 -> -104.895 | AQ15: =AR15/100 -> -9.99 | AR15: -999 | AT15: =(H15*Q15)*((1/Q15^2)-(1/I15^2)) -> -0.15418709 | AU15: =(2*H15*Q15)*((1/I15^2)-(1/Q15^2)) -> 0.30837417 | AV15: =(F15-H15)/((F15*H15)^0.5) -> 0.27057959 | AW15: =Q15/H15 -> 1.4364863 | AX15: =((ATAN(AV15))^(-1))*3.14 -> 11.882599 | AY15: =IF(AV15>0.1,"SUB-VERTICAL",IF(AV15<0,"SUB-HORIZONTAL","MERGULHO")) -> SUB-VERTICAL | AZ15: =IF(AV15>0.1,"1",IF(AV15<0,"2","3")) -> 1 | BA15: =(R15+S15)/2 -> 1.33805
A16: 5575.8207 | B16: 130.266 | C16: 134.4763 | D16: 154.4576 | E16: 151.4387 | F16: 144.6739 | G16: 148.7505 | H16: 98.3472 | I16: =(1/(1/B16)+(1/M16)+(1/C16)+(1/N16)) -> 130.28939 | J16: =G16/145.9555 -> 1.0191497 | K16: =-LOG(AD16)-LOG(J16) -> 0.97057273 | L16: =(M16+N16+O16+B16+C16+D16)/6 -> 135.65277 | M16: 123.2936 | N16: 127.4831 | O16: 143.94 | P16: 135.4897 | Q16: 140.7151 | R16: 2.464 | S16: 0.2121 | T16: 25.5975 | U16: -999 | V16: 4351.2993 | X16: 123.2936 | Y16: 2367.2405 | Z16: -999 | AA16: -999 | AB16: =W16+$W$6*R16+$W$7*S16+$W$8*T16+$W$9*U16 -> -2184.4039 | AC16: 443.7227 | AD16: 0.105 | AE16: 0.105 | AF16: 0.1069 | AG16: 0.1069 | AH16: -999 | AI16: =Z16^(1-1.89) -> #NUM! | AJ16: =G16/H16 -> 1.5125037 | AK16: =ABS(AJ16-1) -> 0.51250366 | AL16: =F16/B16 -> 1.1106037 | AM16: =ABS(AL16-1) -> 0.11060369 | AO16: =((B16+Q16)/2)*(Z16^3)/((1-Z16)^2) -> -135084.48 | AP16: =Z16*AD16 -> -104.895 | AQ16: =AR16/100 -> -9.99 | AR16: -999 | AT16: =(H16*Q16)*((1/Q16^2)-(1/I16^2)) -> -0.11632827 | AU16: =(2*H16*Q16)*((1/I16^2)-(1/Q16^2)) -> 0.23265654 | AV16: =(F16-H16)/((F16*H16)^0.5) -> 0.38837858 | AW16: =Q16/H16 -> 1.4307992 | AX16: =((ATAN(AV16))^(-1))*3.14 -> 8.4762247 | AY16: =IF(AV16>0.1,"SUB-VERTICAL",IF(AV16<0,"SUB-HORIZONTAL","MERGULHO")) -> SUB-VERTICAL | AZ16: =IF(AV16>0.1,"1",IF(AV16<0,"2","3")) -> 1 | BA16: =(R16+S16)/2 -> 1.33805
A17: 5575.8969 | B17: 122.2248 | C17: 135.6659 | D17: 156.9107 | E17: 142.3192 | F17: 136.368 | G17: 141.0962 | H17: 93.9267 | I17: =(1/(1/B17)+(1/M17)+(1/C17)+(1/N17)) -> 122.2487 | J17: =G17/145.9555 -> 0.96670698 | K17: =-LOG(AD17)-LOG(J17) -> 0.99725442 | L17: =(M17+N17+O17+B17+C17+D17)/6 -> 132.62532 | M17: 119.3947 | N17: 122.6002 | O17: 138.9556 | P17: 129.0573 | Q17: 134.7763 | R17: 2.4696 | S17: 0.2124 | T17: 27.8408 | U17: -999 | V17: 4451.2808 | X17: 119.3947 | Y17: 2408.386 | Z17: -999 | AA17: -999 | AB17: =W17+$W$6*R17+$W$7*S17+$W$8*T17+$W$9*U17 -> -2189.0277 | AC17: 461.0509 | AD17: 0.1041 | AE17: 0.1041 | AF17: 0.1122 | AG17: 0.1122 | AH17: -999 | AI17: =Z17^(1-1.89) -> #NUM! | AJ17: =G17/H17 -> 1.5021948 | AK17: =ABS(AJ17-1) -> 0.5021948 | AL17: =F17/B17 -> 1.1157146 | AM17: =ABS(AL17-1) -> 0.11571465 | AO17: =((B17+Q17)/2)*(Z17^3)/((1-Z17)^2) -> -128115.43 | AP17: =Z17*AD17 -> -103.9959 | AQ17: =AR17/100 -> -9.99 | AR17: -999 | AT17: =(H17*Q17)*((1/Q17^2)-(1/I17^2)) -> -0.15015166 | AU17: =(2*H17*Q17)*((1/I17^2)-(1/Q17^2)) -> 0.30030333 | AV17: =(F17-H17)/((F17*H17)^0.5) -> 0.37500574 | AW17: =Q17/H17 -> 1.4349094 | AX17: =((ATAN(AV17))^(-1))*3.14 -> 8.7519863 | AY17: =IF(AV17>0.1,"SUB-VERTICAL",IF(AV17<0,"SUB-HORIZONTAL","MERGULHO")) -> SUB-VERTICAL | AZ17: =IF(AV17>0.1,"1",IF(AV17<0,"2","3")) -> 1 | BA17: =(R17+S17)/2 -> 1.341
A18: 5575.9731 | B18: 115.9625 | C18: 134.9199 | D18: 153.1231 | E18: 131.8428 | F18: 126.833 | G18: 132.1896 | H18: 90.3795 | I18: =(1/(1/B18)+(1/M18)+(1/C18)+(1/N18)) -> 115.9871 | J18: =G18/145.9555 -> 0.90568427 | K18: =-LOG(AD18)-LOG(J18) -> 1.0255724 | L18: =(M18+N18+O18+B18+C18+D18)/6 -> 128.56905 | M18: 114.6388 | N18: 118.0813 | O18: 134.6887 | P18: 125.0743 | Q18: 133.6515 | R18: 2.4696 | S18: 0.2124 | T18: 27.8408 | U18: -999 | V18: 4451.2808 | X18: 114.6388 | Y18: 2408.386 | Z18: -999 | AA18: -999 | AB18: =W18+$W$6*R18+$W$7*S18+$W$8*T18+$W$9*U18 -> -2189.0277 | AC18: 461.0509 | AD18: 0.1041 | AE18: 0.1041 | AF18: 0.1122 | AG18: 0.1122 | AH18: -999 | AI18: =Z18^(1-1.89) -> #NUM! | AJ18: =G18/H18 -> 1.462606 | AK18: =ABS(AJ18-1) -> 0.46260601 | AL18: =F18/B18 -> 1.0937415 | AM18: =ABS(AL18-1) -> 0.093741511 | AO18: =((B18+Q18)/2)*(Z18^3)/((1-Z18)^2) -> -124432.95 | AP18: =Z18*AD18 -> -103.9959 | AQ18: =AR18/100 -> -9.99 | AR18: -999 | AT18: =(H18*Q18)*((1/Q18^2)-(1/I18^2)) -> -0.22165995 | AU18: =(2*H18*Q18)*((1/I18^2)-(1/Q18^2)) -> 0.44331991 | AV18: =(F18-H18)/((F18*H18)^0.5) -> 0.34047728 | AW18: =Q18/H18 -> 1.4787811 | AX18: =((ATAN(AV18))^(-1))*3.14 -> 9.5683205 | AY18: =IF(AV18>0.1,"SUB-VERTICAL",IF(AV18<0,"SUB-HORIZONTAL","MERGULHO")) -> SUB-VERTICAL | AZ18: =IF(AV18>0.1,"1",IF(AV18<0,"2","3")) -> 1 | BA18: =(R18+S18)/2 -> 1.341
A19: 5576.0493 | B19: 107.6091 | C19: 132.4768 | D19: 146.3292 | E19: 129.5309 | F19: 124.8763 | G19: 128.3608 | H19: 87.5612 | I19: =(1/(1/B19)+(1/M19)+(1/C19)+(1/N19)) -> 107.63441 | J19: =G19/145.9555 -> 0.87945161 | K19: =-LOG(AD19)-LOG(J19) -> 0.99698256 | L19: =(M19+N19+O19+B19+C19+D19)/6 -> 123.56095 | M19: 110.0984 | N19: 115.2661 | O19: 129.5861 | P19: 120.4453 | Q19: 132.5767 | R19: 2.4793 | S19: 0.2034 | T19: 29.8867 | U19: -999 | V19: 4558.6289 | X19: 110.0984 | Y19: 2492.4656 | Z19: -999 | AA19: -999 | AB19: =W19+$W$6*R19+$W$7*S19+$W$8*T19+$W$9*U19 -> -2187.7181 | AC19: -999 | AD19: 0.1145 | AE19: 0.1145 | AF19: 0.1213 | AG19: 0.1213 | AH19: -999 | AI19: =Z19^(1-1.89) -> #NUM! | AJ19: =G19/H19 -> 1.4659552 | AK19: =ABS(AJ19-1) -> 0.46595524 | AL19: =F19/B19 -> 1.1604623 | AM19: =ABS(AL19-1) -> 0.16046227 | AO19: =((B19+Q19)/2)*(Z19^3)/((1-Z19)^2) -> -119732.98 | AP19: =Z19*AD19 -> -114.3855 | AQ19: =AR19/100 -> -9.99 | AR19: -999 | AT19: =(H19*Q19)*((1/Q19^2)-(1/I19^2)) -> -0.34156371 | AU19: =(2*H19*Q19)*((1/I19^2)-(1/Q19^2)) -> 0.68312742 | AV19: =(F19-H19)/((F19*H19)^0.5) -> 0.3568525 | AW19: =Q19/H19 -> 1.5141033 | AX19: =((ATAN(AV19))^(-1))*3.14 -> 9.1607577 | AY19: =IF(AV19>0.1,"SUB-VERTICAL",IF(AV19<0,"SUB-HORIZONTAL","MERGULHO")) -> SUB-VERTICAL | AZ19: =IF(AV19>0.1,"1",IF(AV19<0,"2","3")) -> 1 | BA19: =(R19+S19)/2 -> 1.34135
A20: 5576.1255 | B20: 107.2979 | C20: 125.2765 | D20: 135.2405 | E20: 126.9248 | F20: 122.6799 | G20: 125.9829 | H20: 86.1738 | I20: =(1/(1/B20)+(1/M20)+(1/C20)+(1/N20)) -> 107.32426 | J20: =G20/145.9555 -> 0.86315966 | K20: =-LOG(AD20)-LOG(J20) -> 1.0051034 | L20: =(M20+N20+O20+B20+C20+D20)/6 -> 118.03988 | M20: 106.4133 | N20: 111.3804 | O20: 122.6307 | P20: 114.0068 | Q20: 127.8098 | R20: 2.4793 | S20: 0.2034 | T20: 29.8867 | U20: -999 | V20: 4558.6289 | X20: 106.4133 | Y20: 2492.4656 | Z20: -999 | AA20: -999 | AB20: =W20+$W$6*R20+$W$7*S20+$W$8*T20+$W$9*U20 -> -2187.7181 | AC20: -999 | AD20: 0.1145 | AE20: 0.1145 | AF20: 0.1213 | AG20: 0.1213 | AH20: -999 | AI20: =Z20^(1-1.89) -> #NUM! | AJ20: =G20/H20 -> 1.4619629 | AK20: =ABS(AJ20-1) -> 0.46196292 | AL20: =F20/B20 -> 1.1433579 | AM20: =ABS(AL20-1) -> 0.14335788 | AO20: =((B20+Q20)/2)*(Z20^3)/((1-Z20)^2) -> -117201.54 | AP20: =Z20*AD20 -> -114.3855 | AQ20: =AR20/100 -> -9.99 | AR20: -999 | AT20: =(H20*Q20)*((1/Q20^2)-(1/I20^2)) -> -0.28195403 | AU20: =(2*H20*Q20)*((1/I20^2)-(1/Q20^2)) -> 0.56390805 | AV20: =(F20-H20)/((F20*H20)^0.5) -> 0.3550513 | AW20: =Q20/H20 -> 1.4831631 | AX20: =((ATAN(AV20))^(-1))*3.14 -> 9.2036833 | AY20: =IF(AV20>0.1,"SUB-VERTICAL",IF(AV20<0,"SUB-HORIZONTAL","MERGULHO")) -> SUB-VERTICAL | AZ20: =IF(AV20>0.1,"1",IF(AV20<0,"2","3")) -> 1 | BA20: =(R20+S20)/2 -> 1.34135
A21: 5576.2017 | B21: 106.5888 | C21: 112.6309 | D21: 121.693 | E21: 115.4466 | F21: 111.8992 | G21: 115.2712 | H21: 85.0474 | I21: =(1/(1/B21)+(1/M21)+(1/C21)+(1/N21)) -> 106.61674 | J21: =G21/145.9555 -> 0.78976948 | K21: =-LOG(AD21)-LOG(J21) -> 0.9959688 | L21: =(M21+N21+O21+B21+C21+D21)/6 -> 111.32372 | M21: 103.2692 | N21: 106.6851 | O21: 117.0753 | P21: 107.0333 | Q21: 122.3071 | R21: 2.4867 | S21: 0.1878 | T21: 31.9041 | U21: -999 | V21: 4640.0552 | X21: 103.2692 | Y21: 2577.0005 | Z21: -999 | AA21: -999 | AB21: =W21+$W$6*R21+$W$7*S21+$W$8*T21+$W$9*U21 -> -2180.2694 | AC21: 426.6025 | AD21: 0.1278 | AE21: 0.1278 | AF21: 0.1337 | AG21: 0.1337 | AH21: -999 | AI21: =Z21^(1-1.89) -> #NUM! | AJ21: =G21/H21 -> 1.3553759 | AK21: =ABS(AJ21-1) -> 0.35537594 | AL21: =F21/B21 -> 1.0498214 | AM21: =ABS(AL21-1) -> 0.04982137 | AO21: =((B21+Q21)/2)*(Z21^3)/((1-Z21)^2) -> -114104.95 | AP21: =Z21*AD21 -> -127.6722 | AQ21: =AR21/100 -> -9.99 | AR21: -999 | AT21: =(H21*Q21)*((1/Q21^2)-(1/I21^2)) -> -0.21972661 | AU21: =(2*H21*Q21)*((1/I21^2)-(1/Q21^2)) -> 0.43945323 | AV21: =(F21-H21)/((F21*H21)^0.5) -> 0.27525131 | AW21: =Q21/H21 -> 1.4381051 | AX21: =((ATAN(AV21))^(-1))*3.14 -> 11.690253 | AY21: =IF(AV21>0.1,"SUB-VERTICAL",IF(AV21<0,"SUB-HORIZONTAL","MERGULHO")) -> SUB-VERTICAL | AZ21: =IF(AV21>0.1,"1",IF(AV21<0,"2","3")) -> 1 | BA21: =(R21+S21)/2 -> 1.33725
... A84: 5581.0023 | B84: 515.9935 | C84: 678.8842 | D84: 857.6448 | E84: 580.2955 | F84: 547.6121 | G84: 563.2166 | H84: 543.7844 | I84: =(1/(1/B84)+(1/M84)+(1/C84)+(1/N84)) -> 515.9978 | J84: =G84/145.9555 -> 3.8588241 | K84: =-LOG(AD84)-LOG(J84) -> 0.56045549 | L84: =(M84+N84+O84+B84+C84+D84)/6 -> 706.41347 | M84: 759.2965 | N84: 662.1561 | O84: 764.5057 | P84: 678.0287 | Q84: 595.6652 | R84: 2.5192 | S84: 0.1742 | T84: 44.5872 | U84: -999 | V84: 4664.5674 | X84: 759.2965 | Y84: 2902.229 | Z84: -999 | AA84: -999 | AB84: =W84+$W$6*R84+$W$7*S84+$W$8*T84+$W$9*U84 -> -2194.6609 | AC84: 330.8687 | AD84: 0.0713 | AE84: 0.0713 | AF84: 0.0881 | AG84: 0.0881 | AH84: -999 | AI84: =Z84^(1-1.89) -> #NUM! | AJ84: =G84/H84 -> 1.0357351 | AK84: =ABS(AJ84-1) -> 0.035735119 | AL84: =F84/B84 -> 1.0612771 | AM84: =ABS(AL84-1) -> 0.061277128 | AO84: =((B84+Q84)/2)*(Z84^3)/((1-Z84)^2) -> -554163.53 | AP84: =Z84*AD84 -> -71.2287 | AQ84: =AR84/100 -> -9.99 | AR84: -999 | AT84: =(H84*Q84)*((1/Q84^2)-(1/I84^2)) -> -0.30365652 | AU84: =(2*H84*Q84)*((1/I84^2)-(1/Q84^2)) -> 0.60731304 | AV84: =(F84-H84)/((F84*H84)^0.5) -> 0.0070143592 | AW84: =Q84/H84 -> 1.0954069 | AX84: =((ATAN(AV84))^(-1))*3.14 -> 447.66049 | AY84: =IF(AV84>0.1,"SUB-VERTICAL",IF(AV84<0,"SUB-HORIZONTAL","MERGULHO")) -> MERGULHO | AZ84: =IF(AV84>0.1,"1",IF(AV84<0,"2","3")) -> 3 | BA84: =(R84+S84)/2 -> 1.3467
A85: 5581.0785 | B85: 801.8865 | C85: 1074.4752 | D85: 1288.1257 | E85: 676.6855 | F85: 663.414 | G85: 653.2498 | H85: 609.5341 | I85: =(1/(1/B85)+(1/M85)+(1/C85)+(1/N85)) -> 801.88956 | J85: =G85/145.9555 -> 4.4756779 | K85: =-LOG(AD85)-LOG(J85) -> 0.51029209 | L85: =(M85+N85+O85+B85+C85+D85)/6 -> 1002.2478 | M85: 1007.233 | N85: 880.0674 | O85: 961.6991 | P85: 968.5748 | Q85: 745.1599 | R85: 2.5105 | S85: 0.1445 | T85: 38.0232 | U85: 4.1077 | V85: 4572.6689 | X85: 1007.233 | Y85: 2964.7544 | Z85: 0.171 | AA85: 84.5 | AB85: =W85+$W$6*R85+$W$7*S85+$W$8*T85+$W$9*U85 -> -1128.9794 | AC85: 316.763 | AD85: 0.069 | AE85: 0.069 | AF85: 0.0764 | AG85: 0.0764 | AH85: 4.1077 | AI85: =Z85^(1-1.89) -> 4.8154121 | AJ85: =G85/H85 -> 1.0717199 | AK85: =ABS(AJ85-1) -> 0.071719859 | AL85: =F85/B85 -> 0.82731658 | AM85: =ABS(AL85-1) -> 0.17268342 | AO85: =((B85+Q85)/2)*(Z85^3)/((1-Z85)^2) -> 5.6279809 | AP85: =Z85*AD85 -> 0.011799 | AQ85: =AR85/100 -> 0.00171 | AR85: 0.171 | AS85: 0.116 | AT85: =(H85*Q85)*((1/Q85^2)-(1/I85^2)) -> 0.11164359 | AU85: =(2*H85*Q85)*((1/I85^2)-(1/Q85^2)) -> -0.22328718 | AV85: =(F85-H85)/((F85*H85)^0.5) -> 0.08472966 | AW85: =Q85/H85 -> 1.2225073 | AX85: =((ATAN(AV85))^(-1))*3.14 -> 37.147556 | AY85: =IF(AV85>0.1,"SUB-VERTICAL",IF(AV85<0,"SUB-HORIZONTAL","MERGULHO")) -> MERGULHO | AZ85: =IF(AV85>0.1,"1",IF(AV85<0,"2","3")) -> 3 | BA85: =(R85+S85)/2 -> 1.3275
A86: 5581.1547 | B86: 1039.2368 | C86: 1069.1127 | D86: 1403.1847 | E86: 664.7947 | F86: 639.3735 | G86: 649.8528 | H86: 594.5243 | I86: =(1/(1/B86)+(1/M86)+(1/C86)+(1/N86)) -> 1039.2396 | J86: =G86/145.9555 -> 4.4524036 | K86: =-LOG(AD86)-LOG(J86) -> 0.51255638 | L86: =(M86+N86+O86+B86+C86+D86)/6 -> 1123.6305 | M86: 1156.2897 | N86: 974.4163 | O86: 1099.543 | P86: 1084.7289 | Q86: 892.7764 | R86: 2.5105 | S86: 0.1445 | T86: 38.0232 | U86: 4.1077 | V86: 4572.6689 | X86: 1156.2897 | Y86: 2964.7544 | Z86: 0.171 | AA86: 84.5 | AB86: =W86+$W$6*R86+$W$7*S86+$W$8*T86+$W$9*U86 -> -1128.9794 | AC86: 316.763 | AD86: 0.069 | AE86: 0.069 | AF86: 0.0764 | AG86: 0.0764 | AH86: 4.1077 | AI86: =Z86^(1-1.89) -> 4.8154121 | AJ86: =G86/H86 -> 1.0930635 | AK86: =ABS(AJ86-1) -> 0.093063479 | AL86: =F86/B86 -> 0.6152337 | AM86: =ABS(AL86-1) -> 0.3847663 | AO86: =((B86+Q86)/2)*(Z86^3)/((1-Z86)^2) -> 7.0284468 | AP86: =Z86*AD86 -> 0.011799 | AQ86: =AR86/100 -> 0.00171 | AR86: 0.171 | AS86: 0.174 | AT86: =(H86*Q86)*((1/Q86^2)-(1/I86^2)) -> 0.17447565 | AU86: =(2*H86*Q86)*((1/I86^2)-(1/Q86^2)) -> -0.34895131 | AV86: =(F86-H86)/((F86*H86)^0.5) -> 0.07274323 | AW86: =Q86/H86 -> 1.5016651 | AX86: =((ATAN(AV86))^(-1))*3.14 -> 43.24156 | AY86: =IF(AV86>0.1,"SUB-VERTICAL",IF(AV86<0,"SUB-HORIZONTAL","MERGULHO")) -> MERGULHO | AZ86: =IF(AV86>0.1,"1",IF(AV86<0,"2","3")) -> 3 | BA86: =(R86+S86)/2 -> 1.3275
A87: 5581.2309 | B87: 1033.7458 | C87: 1031.6194 | D87: 1243.823 | E87: 611.2242 | F87: 571.7587 | G87: 592.7784 | H87: 594.8344 | I87: =(1/(1/B87)+(1/M87)+(1/C87)+(1/N87)) -> 1033.7486 | J87: =G87/145.9555 -> 4.0613639 | K87: =-LOG(AD87)-LOG(J87) -> 0.48986977 | L87: =(M87+N87+O87+B87+C87+D87)/6 -> 1119.2082 | M87: 1229.8741 | N87: 1019.1733 | O87: 1157.0135 | P87: 1039.9141 | Q87: 931.8405 | R87: 2.5158 | S87: 0.1165 | T87: 34.0681 | U87: -999 | V87: 4500.1777 | X87: 1229.8741 | Y87: 2936.7427 | Z87: -999 | AA87: -999 | AB87: =W87+$W$6*R87+$W$7*S87+$W$8*T87+$W$9*U87 -> -2137.4683 | AC87: 257.6049 | AD87: 0.0797 | AE87: 0.0797 | AF87: 0.0804 | AG87: 0.0683 | AH87: -999 | AI87: =Z87^(1-1.89) -> #NUM! | AJ87: =G87/H87 -> 0.99654358 | AK87: =ABS(AJ87-1) -> 0.0034564242 | AL87: =F87/B87 -> 0.5530941 | AM87: =ABS(AL87-1) -> 0.4469059 | AO87: =((B87+Q87)/2)*(Z87^3)/((1-Z87)^2) -> -979847.72 | AP87: =Z87*AD87 -> -79.6203 | AQ87: =AR87/100 -> -9.99 | AR87: -999 | AT87: =(H87*Q87)*((1/Q87^2)-(1/I87^2)) -> 0.11965364 | AU87: =(2*H87*Q87)*((1/I87^2)-(1/Q87^2)) -> -0.23930729 | AV87: =(F87-H87)/((F87*H87)^0.5) -> -0.039568579 | AW87: =Q87/H87 -> 1.5665545 | AX87: =((ATAN(AV87))^(-1))*3.14 -> -79.397293 | AY87: =IF(AV87>0.1,"SUB-VERTICAL",IF(AV87<0,"SUB-HORIZONTAL","MERGULHO")) -> SUB-HORIZONTAL | AZ87: =IF(AV87>0.1,"1",IF(AV87<0,"2","3")) -> 2 | BA87: =(R87+S87)/2 -> 1.31615
A88: 5581.3071 | B88: 1047.7156 | C88: 1065.2152 | D88: 1479.6067 | E88: 667.1757 | F88: 603.1235 | G88: 624.4707 | H88: 662.9927 | I88: =(1/(1/B88)+(1/M88)+(1/C88)+(1/N88)) -> 1047.7184 | J88: =G88/145.9555 -> 4.2785006 | K88: =-LOG(AD88)-LOG(J88) -> 0.46725008 | L88: =(M88+N88+O88+B88+C88+D88)/6 -> 1149.7333 | M88: 1195.2133 | N88: 1023.6471 | O88: 1087.0022 | P88: 981.4796 | Q88: 869.8414 | R88: 2.5158 | S88: 0.1165 | T88: 34.0681 | U88: -999 | V88: 4500.1777 | X88: 1195.2133 | Y88: 2936.7427 | Z88: -999 | AA88: -999 | AB88: =W88+$W$6*R88+$W$7*S88+$W$8*T88+$W$9*U88 -> -2137.4683 | AC88: 257.6049 | AD88: 0.0797 | AE88: 0.0797 | AF88: 0.0804 | AG88: 0.0683 | AH88: -999 | AI88: =Z88^(1-1.89) -> #NUM! | AJ88: =G88/H88 -> 0.9418968 | AK88: =ABS(AJ88-1) -> 0.058103204 | AL88: =F88/B88 -> 0.57565574 | AM88: =ABS(AL88-1) -> 0.42434426 | AO88: =((B88+Q88)/2)*(Z88^3)/((1-Z88)^2) -> -955905.04 | AP88: =Z88*AD88 -> -79.6203 | AQ88: =AR88/100 -> -9.99 | AR88: -999 | AT88: =(H88*Q88)*((1/Q88^2)-(1/I88^2)) -> 0.23683624 | AU88: =(2*H88*Q88)*((1/I88^2)-(1/Q88^2)) -> -0.47367248 | AV88: =(F88-H88)/((F88*H88)^0.5) -> -0.09467732 | AW88: =Q88/H88 -> 1.3119924 | AX88: =((ATAN(AV88))^(-1))*3.14 -> -33.264142 | AY88: =IF(AV88>0.1,"SUB-VERTICAL",IF(AV88<0,"SUB-HORIZONTAL","MERGULHO")) -> SUB-HORIZONTAL | AZ88: =IF(AV88>0.1,"1",IF(AV88<0,"2","3")) -> 2 | BA88: =(R88+S88)/2 -> 1.31615
A89: 5581.3833 | B89: 935.3281 | C89: 979.4077 | D89: 1379.9121 | E89: 617.846 | F89: 565.6111 | G89: 573.5693 | H89: 662.9252 | I89: =(1/(1/B89)+(1/M89)+(1/C89)+(1/N89)) -> 935.33127 | J89: =G89/145.9555 -> 3.9297546 | K89: =-LOG(AD89)-LOG(J89) -> 0.44043287 | L89: =(M89+N89+O89+B89+C89+D89)/6 -> 1019.9138 | M89: 1003.3738 | N89: 871.4689 | O89: 949.9924 | P89: 861.6324 | Q89: 734.7858 | R89: 2.5319 | S89: 0.1019 | T89: 36.2354 | U89: 4.0141 | V89: 4540.6479 | X89: 1003.3738 | Y89: 2805.4128 | Z89: 0.176 | AA89: 5.62 | AB89: =W89+$W$6*R89+$W$7*S89+$W$8*T89+$W$9*U89 -> -1102.056 | AC89: -999 | AD89: 0.0923 | AE89: 0.0923 | AF89: 0.0923 | AG89: 0.0687 | AH89: 4.0141 | AI89: =Z89^(1-1.89) -> 4.6934665 | AJ89: =G89/H89 -> 0.86520968 | AK89: =ABS(AJ89-1) -> 0.13479032 | AL89: =F89/B89 -> 0.60471946 | AM89: =ABS(AL89-1) -> 0.39528054 | AO89: =((B89+Q89)/2)*(Z89^3)/((1-Z89)^2) -> 6.7050138 | AP89: =Z89*AD89 -> 0.0162448 | AQ89: =AR89/100 -> 0.00176 | AR89: 0.176 | AS89: 0.345 | AT89: =(H89*Q89)*((1/Q89^2)-(1/I89^2)) -> 0.34540819 | AU89: =(2*H89*Q89)*((1/I89^2)-(1/Q89^2)) -> -0.69081638 | AV89: =(F89-H89)/((F89*H89)^0.5) -> -0.15892219 | AW89: =Q89/H89 -> 1.1083993 | AX89: =((ATAN(AV89))^(-1))*3.14 -> -19.923329 | AY89: =IF(AV89>0.1,"SUB-VERTICAL",IF(AV89<0,"SUB-HORIZONTAL","MERGULHO")) -> SUB-HORIZONTAL | AZ89: =IF(AV89>0.1,"1",IF(AV89<0,"2","3")) -> 2 | BA89: =(R89+S89)/2 -> 1.3169
A90: 5581.4595 | B90: 758.4761 | C90: 723.1504 | D90: 988.6627 | E90: 511.4042 | F90: 480.6629 | G90: 464.1394 | H90: 611.1597 | I90: =(1/(1/B90)+(1/M90)+(1/C90)+(1/N90)) -> 758.48028 | J90: =G90/145.9555 -> 3.1800062 | K90: =-LOG(AD90)-LOG(J90) -> 0.53237033 | L90: =(M90+N90+O90+B90+C90+D90)/6 -> 786.78672 | M90: 758.9992 | N90: 676.352 | O90: 815.0799 | P90: 695.138 | Q90: 574.1118 | R90: 2.5319 | S90: 0.1019 | T90: 36.2354 | U90: 4.0141 | V90: 4540.6479 | X90: 758.9992 | Y90: 2805.4128 | Z90: 0.176 | AA90: 5.62 | AB90: =W90+$W$6*R90+$W$7*S90+$W$8*T90+$W$9*U90 -> -1102.056 | AC90: -999 | AD90: 0.0923 | AE90: 0.0923 | AF90: 0.0923 | AG90: 0.0687 | AH90: 4.0141 | AI90: =Z90^(1-1.89) -> 4.6934665 | AJ90: =G90/H90 -> 0.75944045 | AK90: =ABS(AJ90-1) -> 0.24055955 | AL90: =F90/B90 -> 0.63372188 | AM90: =ABS(AL90-1) -> 0.36627812 | AO90: =((B90+Q90)/2)*(Z90^3)/((1-Z90)^2) -> 5.3499466 | AP90: =Z90*AD90 -> 0.0162448 | AQ90: =AR90/100 -> 0.00176 | AR90: 0.176 | AS90: 0.454 | AT90: =(H90*Q90)*((1/Q90^2)-(1/I90^2)) -> 0.45462525 | AU90: =(2*H90*Q90)*((1/I90^2)-(1/Q90^2)) -> -0.90925049 | AV90: =(F90-H90)/((F90*H90)^0.5) -> -0.24076991 | AW90: =Q90/H90 -> 0.93938098 | AX90: =((ATAN(AV90))^(-1))*3.14 -> -13.289721 | AY90: =IF(AV90>0.1,"SUB-VERTICAL",IF(AV90<0,"SUB-HORIZONTAL","MERGULHO")) -> SUB-HORIZONTAL | AZ90: =IF(AV90>0.1,"1",IF(AV90<0,"2","3")) -> 2 | BA90: =(R90+S90)/2 -> 1.3169
A91: 5581.5357 | B91: 559.63 | C91: 562.6732 | D91: 709.2905 | E91: 403.1908 | F91: 384.4682 | G91: 385.1412 | H91: 564.1857 | I91: =(1/(1/B91)+(1/M91)+(1/C91)+(1/N91)) -> 559.63538 | J91: =G91/145.9555 -> 2.6387577 | K91: =-LOG(AD91)-LOG(J91) -> 0.54277066 | L91: =(M91+N91+O91+B91+C91+D91)/6 -> 605.69627 | M91: 573.7358 | N91: 536.6766 | O91: 692.1715 | P91: 565.4944 | Q91: 478.7786 | R91: 2.5417 | S91: 0.1062 | T91: 41.1261 | U91: -999 | V91: 4779.3525 | X91: 573.7358 | Y91: 2689.7485 | Z91: -999 | AA91: -999 | AB91: =W91+$W$6*R91+$W$7*S91+$W$8*T91+$W$9*U91 -> -2146.376 | AC91: 185.319 | AD91: 0.1086 | AE91: 0.1086 | AF91: 0.1086 | AG91: 0.0708 | AH91: -999 | AI91: =Z91^(1-1.89) -> #NUM! | AJ91: =G91/H91 -> 0.6826497 | AK91: =ABS(AJ91-1) -> 0.3173503 | AL91: =F91/B91 -> 0.68700427 | AM91: =ABS(AL91-1) -> 0.31299573 | AO91: =((B91+Q91)/2)*(Z91^3)/((1-Z91)^2) -> -517648.24 | AP91: =Z91*AD91 -> -108.4914 | AQ91: =AR91/100 -> -9.99 | AR91: -999 | AT91: =(H91*Q91)*((1/Q91^2)-(1/I91^2)) -> 0.31591046 | AU91: =(2*H91*Q91)*((1/I91^2)-(1/Q91^2)) -> -0.63182091 | AV91: =(F91-H91)/((F91*H91)^0.5) -> -0.3858772 | AW91: =Q91/H91 -> 0.84861881 | AX91: =((ATAN(AV91))^(-1))*3.14 -> -8.5262932 | AY91: =IF(AV91>0.1,"SUB-VERTICAL",IF(AV91<0,"SUB-HORIZONTAL","MERGULHO")) -> SUB-HORIZONTAL | AZ91: =IF(AV91>0.1,"1",IF(AV91<0,"2","3")) -> 2 | BA91: =(R91+S91)/2 -> 1.32395
A92: 5581.6119 | B92: 406.0007 | C92: 447.9662 | D92: 540.8618 | E92: 352.9025 | F92: 339.0969 | G92: 351.4859 | H92: 506.3126 | I92: =(1/(1/B92)+(1/M92)+(1/C92)+(1/N92)) -> 406.00727 | J92: =G92/145.9555 -> 2.4081717 | K92: =-LOG(AD92)-LOG(J92) -> 0.58248273 | L92: =(M92+N92+O92+B92+C92+D92)/6 -> 486.69817 | M92: 462.7726 | N92: 458.9506 | O92: 603.6371 | P92: 481.5101 | Q92: 423.2158 | R92: 2.5417 | S92: 0.1062 | T92: 41.1261 | U92: -999 | V92: 4779.3525 | X92: 462.7726 | Y92: 2689.7485 | Z92: -999 | AA92: -999 | AB92: =W92+$W$6*R92+$W$7*S92+$W$8*T92+$W$9*U92 -> -2146.376 | AC92: 185.319 | AD92: 0.1086 | AE92: 0.1086 | AF92: 0.1086 | AG92: 0.0708 | AH92: -999 | AI92: =Z92^(1-1.89) -> #NUM! | AJ92: =G92/H92 -> 0.69420729 | AK92: =ABS(AJ92-1) -> 0.30579271 | AL92: =F92/B92 -> 0.8352126 | AM92: =ABS(AL92-1) -> 0.1647874 | AO92: =((B92+Q92)/2)*(Z92^3)/((1-Z92)^2) -> -413365.67 | AP92: =Z92*AD92 -> -108.4914 | AQ92: =AR92/100 -> -9.99 | AR92: -999 | AT92: =(H92*Q92)*((1/Q92^2)-(1/I92^2)) -> -0.10356293 | AU92: =(2*H92*Q92)*((1/I92^2)-(1/Q92^2)) -> 0.20712586 | AV92: =(F92-H92)/((F92*H92)^0.5) -> -0.40355783 | AW92: =Q92/H92 -> 0.83587847 | AX92: =((ATAN(AV92))^(-1))*3.14 -> -8.1862566 | AY92: =IF(AV92>0.1,"SUB-VERTICAL",IF(AV92<0,"SUB-HORIZONTAL","MERGULHO")) -> SUB-HORIZONTAL | AZ92: =IF(AV92>0.1,"1",IF(AV92<0,"2","3")) -> 2 | BA92: =(R92+S92)/2 -> 1.32395
A93: 5581.6881 | B93: 353.5434 | C93: 446.0331 | D93: 472.7209 | E93: 332.5149 | F93: 321.096 | G93: 333.7124 | H93: 456.2232 | I93: =(1/(1/B93)+(1/M93)+(1/C93)+(1/N93)) -> 353.5504 | J93: =G93/145.9555 -> 2.2863983 | K93: =-LOG(AD93)-LOG(J93) -> 0.61390649 | L93: =(M93+N93+O93+B93+C93+D93)/6 -> 444.96587 | M93: 419.9279 | N93: 421.5578 | O93: 556.0121 | P93: 446.669 | Q93: 383.1099 | R93: 2.5285 | S93: 0.1239 | T93: 42.9966 | U93: 4.3106 | V93: 4820.6104 | X93: 419.9279 | Y93: 2660.3748 | Z93: 0.161 | AA93: 38.2 | AB93: =W93+$W$6*R93+$W$7*S93+$W$8*T93+$W$9*U93 -> -1124.414 | AC93: 298.9697 | AD93: 0.1064 | AE93: 0.1064 | AF93: 0.1064 | AG93: 0.0758 | AH93: 4.3106 | AI93: =Z93^(1-1.89) -> 5.0807166 | AJ93: =G93/H93 -> 0.7314674 | AK93: =ABS(AJ93-1) -> 0.2685326 | AL93: =F93/B93 -> 0.9082223 | AM93: =ABS(AL93-1) -> 0.0917777 | AO93: =((B93+Q93)/2)*(Z93^3)/((1-Z93)^2) -> 2.1836692 | AP93: =Z93*AD93 -> 0.0171304 | AQ93: =AR93/100 -> 0.00161 | AR93: 0.161 | AS93: 0.41 | AT93: =(H93*Q93)*((1/Q93^2)-(1/I93^2)) -> -0.2074511 | AU93: =(2*H93*Q93)*((1/I93^2)-(1/Q93^2)) -> 0.41490221 | AV93: =(F93-H93)/((F93*H93)^0.5) -> -0.35305035 | AW93: =Q93/H93 -> 0.83974226 | AX93: =((ATAN(AV93))^(-1))*3.14 -> -9.2519015 | AY93: =IF(AV93>0.1,"SUB-VERTICAL",IF(AV93<0,"SUB-HORIZONTAL","MERGULHO")) -> SUB-HORIZONTAL | AZ93: =IF(AV93>0.1,"1",IF(AV93<0,"2","3")) -> 2 | BA93: =(R93+S93)/2 -> 1.3262
A94: 5581.7643 | B94: 351.5662 | C94: 458.6676 | D94: 501.6991 | E94: 329.9853 | F94: 319.3913 | G94: 329.2165 | H94: 443.9205 | I94: =(1/(1/B94)+(1/M94)+(1/C94)+(1/N94)) -> 351.57325 | J94: =G94/145.9555 -> 2.255595 | K94: =-LOG(AD94)-LOG(J94) -> 0.61979724 | L94: =(M94+N94+O94+B94+C94+D94)/6 -> 445.02123 | M94: 415.8616 | N94: 405.6687 | O94: 536.6642 | P94: 435.868 | Q94: 359.8051 | R94: 2.5285 | S94: 0.1239 | T94: 42.9966 | U94: 4.3106 | V94: 4820.6104 | X94: 415.8616 | Y94: 2660.3748 | Z94: 0.161 | AA94: 38.2 | AB94: =W94+$W$6*R94+$W$7*S94+$W$8*T94+$W$9*U94 -> -1124.414 | AC94: 298.9697 | AD94: 0.1064 | AE94: 0.1064 | AF94: 0.1064 | AG94: 0.0758 | AH94: 4.3106 | AI94: =Z94^(1-1.89) -> 5.0807166 | AJ94: =G94/H94 -> 0.74161139 | AK94: =ABS(AJ94-1) -> 0.25838861 | AL94: =F94/B94 -> 0.90848125 | AM94: =ABS(AL94-1) -> 0.091518752 | AO94: =((B94+Q94)/2)*(Z94^3)/((1-Z94)^2) -> 2.1087255 | AP94: =Z94*AD94 -> 0.0171304 | AQ94: =AR94/100 -> 0.00161 | AR94: 0.161 | AS94: 0.11 | AT94: =(H94*Q94)*((1/Q94^2)-(1/I94^2)) -> -0.058452667 | AU94: =(2*H94*Q94)*((1/I94^2)-(1/Q94^2)) -> 0.11690533 | AV94: =(F94-H94)/((F94*H94)^0.5) -> -0.33071741 | AW94: =Q94/H94 -> 0.81051697 | AX94: =((ATAN(AV94))^(-1))*3.14 -> -9.8311061 | AY94: =IF(AV94>0.1,"SUB-VERTICAL",IF(AV94<0,"SUB-HORIZONTAL","MERGULHO")) -> SUB-HORIZONTAL | AZ94: =IF(AV94>0.1,"1",IF(AV94<0,"2","3")) -> 2 | BA94: =(R94+S94)/2 -> 1.3262
A95: 5581.8405 | B95: 356.668 | C95: 423.8164 | D95: 519.1217 | E95: 332.1964 | F95: 322.296 | G95: 335.662 | H95: 453.7095 | I95: =(1/(1/B95)+(1/M95)+(1/C95)+(1/N95)) -> 356.67521 | J95: =G95/145.9555 -> 2.2997557 | K95: =-LOG(AD95)-LOG(J95) -> 0.66426738 | L95: =(M95+N95+O95+B95+C95+D95)/6 -> 443.21777 | M95: 426.0108 | N95: 400.0862 | O95: 533.6035 | P95: 425.0998 | Q95: 349.7631 | R95: 2.4974 | S95: 0.1438 | T95: 41.4301 | U95: -999 | V95: 4843.7227 | X95: 426.0108 | Y95: 2701.1223 | Z95: -999 | AA95: -999 | AB95: =W95+$W$6*R95+$W$7*S95+$W$8*T95+$W$9*U95 -> -2159.0382 | AC95: 389.4536 | AD95: 0.0942 | AE95: 0.0942 | AF95: 0.0942 | AG95: 0.0787 | AH95: -999 | AI95: =Z95^(1-1.89) -> #NUM! | AJ95: =G95/H95 -> 0.739817 | AK95: =ABS(AJ95-1) -> 0.260183 | AL95: =F95/B95 -> 0.90363027 | AM95: =ABS(AL95-1) -> 0.096369733 | AO95: =((B95+Q95)/2)*(Z95^3)/((1-Z95)^2) -> -352156.96 | AP95: =Z95*AD95 -> -94.1058 | AQ95: =AR95/100 -> -9.99 | AR95: -999 | AT95: =(H95*Q95)*((1/Q95^2)-(1/I95^2)) -> 0.049790065 | AU95: =(2*H95*Q95)*((1/I95^2)-(1/Q95^2)) -> -0.09958013 | AV95: =(F95-H95)/((F95*H95)^0.5) -> -0.34365573 | AW95: =Q95/H95 -> 0.77089658 | AX95: =((ATAN(AV95))^(-1))*3.14 -> -9.4860677 | AY95: =IF(AV95>0.1,"SUB-VERTICAL",IF(AV95<0,"SUB-HORIZONTAL","MERGULHO")) -> SUB-HORIZONTAL | AZ95: =IF(AV95>0.1,"1",IF(AV95<0,"2","3")) -> 2 | BA95: =(R95+S95)/2 -> 1.3206
A96: 5581.9167 | B96: 403.49 | C96: 388.7556 | D96: 484.357 | E96: 328.9037 | F96: 319.9106 | G96: 334.9256 | H96: 474.837 | I96: =(1/(1/B96)+(1/M96)+(1/C96)+(1/N96)) -> 403.49731 | J96: =G96/145.9555 -> 2.2947104 | K96: =-LOG(AD96)-LOG(J96) -> 0.66522122 | L96: =(M96+N96+O96+B96+C96+D96)/6 -> 444.55728 | M96: 444.7903 | N96: 402.2347 | O96: 543.7161 | P96: 421.1289 | Q96: 349.0292 | R96: 2.4974 | S96: 0.1438 | T96: 41.4301 | U96: -999 | V96: 4843.7227 | X96: 444.7903 | Y96: 2701.1223 | Z96: -999 | AA96: -999 | AB96: =W96+$W$6*R96+$W$7*S96+$W$8*T96+$W$9*U96 -> -2159.0382 | AC96: 389.4536 | AD96: 0.0942 | AE96: 0.0942 | AF96: 0.0942 | AG96: 0.0787 | AH96: -999 | AI96: =Z96^(1-1.89) -> #NUM! | AJ96: =G96/H96 -> 0.70534857 | AK96: =ABS(AJ96-1) -> 0.29465143 | AL96: =F96/B96 -> 0.79285881 | AM96: =ABS(AL96-1) -> 0.20714119 | AO96: =((B96+Q96)/2)*(Z96^3)/((1-Z96)^2) -> -375131.95 | AP96: =Z96*AD96 -> -94.1058 | AQ96: =AR96/100 -> -9.99 | AR96: -999 | AT96: =(H96*Q96)*((1/Q96^2)-(1/I96^2)) -> 0.34250396 | AU96: =(2*H96*Q96)*((1/I96^2)-(1/Q96^2)) -> -0.68500791 | AV96: =(F96-H96)/((F96*H96)^0.5) -> -0.39750156 | AW96: =Q96/H96 -> 0.73505055 | AX96: =((ATAN(AV96))^(-1))*3.14 -> -8.2991786 | AY96: =IF(AV96>0.1,"SUB-VERTICAL",IF(AV96<0,"SUB-HORIZONTAL","MERGULHO")) -> SUB-HORIZONTAL | AZ96: =IF(AV96>0.1,"1",IF(AV96<0,"2","3")) -> 2 | BA96: =(R96+S96)/2 -> 1.3206
A97: 5581.9929 | B97: 453.8287 | C97: 410.1525 | D97: 486.7028 | E97: 336.539 | F97: 327.8571 | G97: 340.485 | H97: 501.802 | I97: =(1/(1/B97)+(1/M97)+(1/C97)+(1/N97)) -> 453.83569 | J97: =G97/145.9555 -> 2.3328001 | K97: =-LOG(AD97)-LOG(J97) -> 0.71199915 | L97: =(M97+N97+O97+B97+C97+D97)/6 -> 466.7379 | M97: 470.9291 | N97: 412.07 | O97: 566.7443 | P97: 426.941 | Q97: 352.217 | R97: 2.4658 | S97: 0.1593 | T97: 36.6217 | U97: 4.2893 | V97: 4882.833 | X97: 470.9291 | Y97: 2731.8047 | Z97: 0.162 | AA97: 995 | AB97: =W97+$W$6*R97+$W$7*S97+$W$8*T97+$W$9*U97 -> -1121.6243 | AC97: 405.096 | AD97: 0.0832 | AE97: 0.0832 | AF97: 0.0832 | AG97: 0.074 | AH97: 4.2893 | AI97: =Z97^(1-1.89) -> 5.0527945 | AJ97: =G97/H97 -> 0.6785246 | AK97: =ABS(AJ97-1) -> 0.3214754 | AL97: =F97/B97 -> 0.72242478 | AM97: =ABS(AL97-1) -> 0.27757522 | AO97: =((B97+Q97)/2)*(Z97^3)/((1-Z97)^2) -> 2.4399823 | AP97: =Z97*AD97 -> 0.0134784 | AQ97: =AR97/100 -> 0.00162 | AR97: 0.162 | AS97: 0.56 | AT97: =(H97*Q97)*((1/Q97^2)-(1/I97^2)) -> 0.56658073 | AU97: =(2*H97*Q97)*((1/I97^2)-(1/Q97^2)) -> -1.1331615 | AV97: =(F97-H97)/((F97*H97)^0.5) -> -0.42884782 | AW97: =Q97/H97 -> 0.70190434 | AX97: =((ATAN(AV97))^(-1))*3.14 -> -7.7506891 | AY97: =IF(AV97>0.1,"SUB-VERTICAL",IF(AV97<0,"SUB-HORIZONTAL","MERGULHO")) -> SUB-HORIZONTAL | AZ97: =IF(AV97>0.1,"1",IF(AV97<0,"2","3")) -> 2 | BA97: =(R97+S97)/2 -> 1.31255
A98: 5582.0691 | B98: 473.1146 | C98: 460.2591 | D98: 541.016 | E98: 358.2119 | F98: 349.4585 | G98: 358.1487 | H98: 540.9119 | I98: =(1/(1/B98)+(1/M98)+(1/C98)+(1/N98)) -> 473.12112 | J98: =G98/145.9555 -> 2.4538212 | K98: =-LOG(AD98)-LOG(J98) -> 0.69003376 | L98: =(M98+N98+O98+B98+C98+D98)/6 -> 499.32357 | M98: 503.3021 | N98: 423.3931 | O98: 594.8565 | P98: 439.6122 | Q98: 360.3977 | R98: 2.4658 | S98: 0.1593 | T98: 36.6217 | U98: 4.2893 | V98: 4882.833 | X98: 503.3021 | Y98: 2731.8047 | Z98: 0.162 | AA98: 995 | AB98: =W98+$W$6*R98+$W$7*S98+$W$8*T98+$W$9*U98 -> -1121.6243 | AC98: 405.096 | AD98: 0.0832 | AE98: 0.0832 | AF98: 0.0832 | AG98: 0.074 | AH98: 4.2893 | AI98: =Z98^(1-1.89) -> 5.0527945 | AJ98: =G98/H98 -> 0.66212021 | AK98: =ABS(AJ98-1) -> 0.33787979 | AL98: =F98/B98 -> 0.73863394 | AM98: =ABS(AL98-1) -> 0.26136606 | AO98: =((B98+Q98)/2)*(Z98^3)/((1-Z98)^2) -> 2.5231265 | AP98: =Z98*AD98 -> 0.0134784 | AQ98: =AR98/100 -> 0.00162 | AR98: 0.162 | AS98: 0.629 | AT98: =(H98*Q98)*((1/Q98^2)-(1/I98^2)) -> 0.62998386 | AU98: =(2*H98*Q98)*((1/I98^2)-(1/Q98^2)) -> -1.2599677 | AV98: =(F98-H98)/((F98*H98)^0.5) -> -0.44035407 | AW98: =Q98/H98 -> 0.666278 | AX98: =((ATAN(AV98))^(-1))*3.14 -> -7.5698498 | AY98: =IF(AV98>0.1,"SUB-VERTICAL",IF(AV98<0,"SUB-HORIZONTAL","MERGULHO")) -> SUB-HORIZONTAL | AZ98: =IF(AV98>0.1,"1",IF(AV98<0,"2","3")) -> 2 | BA98: =(R98+S98)/2 -> 1.31255
A99: 5582.1453 | B99: 496.3062 | C99: 470.4284 | D99: 567.2252 | E99: 383.1929 | F99: 373.6865 | G99: 380.292 | H99: 600.7729 | I99: =(1/(1/B99)+(1/M99)+(1/C99)+(1/N99)) -> 496.3125 | J99: =G99/145.9555 -> 2.6055339 | K99: =-LOG(AD99)-LOG(J99) -> 0.71840722 | L99: =(M99+N99+O99+B99+C99+D99)/6 -> 522.49167 | M99: 540.9618 | N99: 429.5568 | O99: 630.4716 | P99: 458.5416 | Q99: 374.1621 | R99: 2.4493 | S99: 0.1724 | T99: 31.5878 | U99: -999 | V99: 4990.0845 | X99: 540.9618 | Y99: 2736.8218 | Z99: -999 | AA99: -999 | AB99: =W99+$W$6*R99+$W$7*S99+$W$8*T99+$W$9*U99 -> -2153.1718 | AC99: -999 | AD99: 0.0734 | AE99: 0.0734 | AF99: 0.0734 | AG99: 0.0665 | AH99: -999 | AI99: =Z99^(1-1.89) -> #NUM! | AJ99: =G99/H99 -> 0.63300458 | AK99: =ABS(AJ99-1) -> 0.36699542 | AL99: =F99/B99 -> 0.75293539 | AM99: =ABS(AL99-1) -> 0.24706461 | AO99: =((B99+Q99)/2)*(Z99^3)/((1-Z99)^2) -> -433929.75 | AP99: =Z99*AD99 -> -73.3266 | AQ99: =AR99/100 -> -9.99 | AR99: -999 | AT99: =(H99*Q99)*((1/Q99^2)-(1/I99^2)) -> 0.69309237 | AU99: =(2*H99*Q99)*((1/I99^2)-(1/Q99^2)) -> -1.3861847 | AV99: =(F99-H99)/((F99*H99)^0.5) -> -0.47927222 | AW99: =Q99/H99 -> 0.62280123 | AX99: =((ATAN(AV99))^(-1))*3.14 -> -7.0257353 | AY99: =IF(AV99>0.1,"SUB-VERTICAL",IF(AV99<0,"SUB-HORIZONTAL","MERGULHO")) -> SUB-HORIZONTAL | AZ99: =IF(AV99>0.1,"1",IF(AV99<0,"2","3")) -> 2 | BA99: =(R99+S99)/2 -> 1.31085
A100: 5582.2215 | B100: 545.3602 | C100: 441.7914 | D100: 572.6639 | E100: 397.2768 | F100: 387.5615 | G100: 396.933 | H100: 672.34 | I100: =(1/(1/B100)+(1/M100)+(1/C100)+(1/N100)) -> 545.36642 | J100: =G100/145.9555 -> 2.7195481 | K100: =-LOG(AD100)-LOG(J100) -> 0.6998072 | L100: =(M100+N100+O100+B100+C100+D100)/6 -> 542.3422 | M100: 583.2471 | N100: 445.9526 | O100: 665.038 | P100: 478.1016 | Q100: 390.321 | R100: 2.4493 | S100: 0.1724 | T100: 31.5878 | U100: -999 | V100: 4990.0845 | X100: 583.2471 | Y100: 2736.8218 | Z100: -999 | AA100: -999 | AB100: =W100+$W$6*R100+$W$7*S100+$W$8*T100+$W$9*U100 -> -2153.1718 | AC100: -999 | AD100: 0.0734 | AE100: 0.0734 | AF100: 0.0734 | AG100: 0.0665 | AH100: -999 | AI100: =Z100^(1-1.89) -> #NUM! | AJ100: =G100/H100 -> 0.59037541 | AK100: =ABS(AJ100-1) -> 0.40962459 | AL100: =F100/B100 -> 0.71065234 | AM100: =ABS(AL100-1) -> 0.28934766 | AO100: =((B100+Q100)/2)*(Z100^3)/((1-Z100)^2) -> -466438.48 | AP100: =Z100*AD100 -> -73.3266 | AQ100: =AR100/100 -> -9.99 | AR100: -999 | AT100: =(H100*Q100)*((1/Q100^2)-(1/I100^2)) -> 0.84019478 | AU100: =(2*H100*Q100)*((1/I100^2)-(1/Q100^2)) -> -1.6803896 | AV100: =(F100-H100)/((F100*H100)^0.5) -> -0.55788208 | AW100: =Q100/H100 -> 0.5805411 | AX100: =((ATAN(AV100))^(-1))*3.14 -> -6.1704794 | AY100: =IF(AV100>0.1,"SUB-VERTICAL",IF(AV100<0,"SUB-HORIZONTAL","MERGULHO")) -> SUB-HORIZONTAL | AZ100: =IF(AV100>0.1,"1",IF(AV100<0,"2","3")) -> 2 | BA100: =(R100+S100)/2 -> 1.31085
A101: 5582.2977 | B101: 618.2883 | C101: 387.4758 | D101: 551.3174 | E101: 420.4649 | F101: 410.2702 | G101: 420.2466 | H101: 753.3162 | I101: =(1/(1/B101)+(1/M101)+(1/C101)+(1/N101)) -> 618.29457 | J101: =G101/145.9555 -> 2.879279 | K101: =-LOG(AD101)-LOG(J101) -> 0.73589558 | L101: =(M101+N101+O101+B101+C101+D101)/6 -> 558.2079 | M101: 641.6483 | N101: 468.4665 | O101: 682.0511 | P101: 500.4282 | Q101: 392.0295 | R101: 2.4442 | S101: 0.19 | T101: 26.0192 | U101: 4.1663 | V101: 5112.6836 | X101: 641.6483 | Y101: 2763.8445 | Z101: 0.168 | AA101: 354 | AB101: =W101+$W$6*R101+$W$7*S101+$W$8*T101+$W$9*U101 -> -1127.1627 | AC101: 436.4892 | AD101: 0.0638 | AE101: 0.0638 | AF101: 0.0638 | AG101: 0.058 | AH101: 4.1663 | AI101: =Z101^(1-1.89) -> 4.8918681 | AJ101: =G101/H101 -> 0.55786216 | AK101: =ABS(AJ101-1) -> 0.44213784 | AL101: =F101/B101 -> 0.66355808 | AM101: =ABS(AL101-1) -> 0.33644192 | AO101: =((B101+Q101)/2)*(Z101^3)/((1-Z101)^2) -> 3.4602637 | AP101: =Z101*AD101 -> 0.0107184 | AQ101: =AR101/100 -> 0.00168 | AR101: 0.168 | AT101: =(H101*Q101)*((1/Q101^2)-(1/I101^2)) -> 1.1490685 | AU101: =(2*H101*Q101)*((1/I101^2)-(1/Q101^2)) -> -2.298137 | AV101: =(F101-H101)/((F101*H101)^0.5) -> -0.61706188 | AW101: =Q101/H101 -> 0.52040498 | AX101: =((ATAN(AV101))^(-1))*3.14 -> -5.679448 | AY101: =IF(AV101>0.1,"SUB-VERTICAL",IF(AV101<0,"SUB-HORIZONTAL","MERGULHO")) -> SUB-HORIZONTAL | AZ101: =IF(AV101>0.1,"1",IF(AV101<0,"2","3")) -> 2 | BA101: =(R101+S101)/2 -> 1.3171
A102: 5582.3739 | B102: 712.4839 | C102: 397.8827 | D102: 608.2162 | E102: 469.2344 | F102: 455.3875 | G102: 468.5294 | H102: 854.5427 | I102: =(1/(1/B102)+(1/M102)+(1/C102)+(1/N102)) -> 712.4899 | J102: =G102/145.9555 -> 3.2100839 | K102: =-LOG(AD102)-LOG(J102) -> 0.68866294 | L102: =(M102+N102+O102+B102+C102+D102)/6 -> 599.5841 | M102: 706.1272 | N102: 482.5685 | O102: 690.2261 | P102: 488.27 | Q102: 392.6326 | R102: 2.4442 | S102: 0.19 | T102: 26.0192 | U102: 4.1663 | V102: 5112.6836 | X102: 706.1272 | Y102: 2763.8445 | Z102: 0.168 | AA102: 354 | AB102: =W102+$W$6*R102+$W$7*S102+$W$8*T102+$W$9*U102 -> -1127.1627 | AC102: 436.4892 | AD102: 0.0638 | AE102: 0.0638 | AF102: 0.0638 | AG102: 0.058 | AH102: 4.1663 | AI102: =Z102^(1-1.89) -> 4.8918681 | AJ102: =G102/H102 -> 0.54828085 | AK102: =ABS(AJ102-1) -> 0.45171915 | AL102: =F102/B102 -> 0.63915479 | AM102: =ABS(AL102-1) -> 0.36084521 | AO102: =((B102+Q102)/2)*(Z102^3)/((1-Z102)^2) -> 3.7849423 | AP102: =Z102*AD102 -> 0.0107184 | AQ102: =AR102/100 -> 0.00168 | AR102: 0.168 | AT102: =(H102*Q102)*((1/Q102^2)-(1/I102^2)) -> 1.5155026 | AU102: =(2*H102*Q102)*((1/I102^2)-(1/Q102^2)) -> -3.0310051 | AV102: =(F102-H102)/((F102*H102)^0.5) -> -0.63985911 | AW102: =Q102/H102 -> 0.45946516 | AX102: =((ATAN(AV102))^(-1))*3.14 -> -5.5163862 | AY102: =IF(AV102>0.1,"SUB-VERTICAL",IF(AV102<0,"SUB-HORIZONTAL","MERGULHO")) -> SUB-HORIZONTAL | AZ102: =IF(AV102>0.1,"1",IF(AV102<0,"2","3")) -> 2 | BA102: =(R102+S102)/2 -> 1.3171
...

Sheet Planilha6
B1: 0.58302083 | D1: :
A2: AORX | B2: AO90 | C2: AORT | D2: AO10 | E2: 1/AO90 | F2: 1/AO10 | L2: Bv | M2: Bh
A3: ohm,m | B3: ohm,m | C3: ohm,m | D3: ohm,m
H4: BV | P4: =4*(10^-7) -> 4e-07 | Q4: =1.2*(10^-7) -> 1.2e-07 | R4: =1/1950 -> 0.00051282051
A5: 221.9146 | B5: 271.66 | C5: 291.7903 | D5: 272.2705 | E5: =1/B5 -> 0.0036810719 | F5: =1/D5 -> 0.003672818 | G5: =A5/(4*(10^-7)) -> 554786500 | H5: =ABS((G5*(E5-F5))/10000) -> 0.45791542 | I5: =A5/(1.2*(10^-7)) -> 1849288333 | J5: =(I5*(E5-0.000513))/10000 -> 585.86785 | L5: =(A5/(4*10^-7))*((1/D5)-(1/A5)) -> -462370.14 | M5: =(A5/(1.2*10^-7))*((1/B5)-(1/1949)) -> 5858523.8 | N5: =L5+M5 -> 5396153.7 | O5: =M5/1000 -> 5858.5238
A6: 200.8569 | B6: 249.0079 | C6: 263.5609 | D6: 244.2342 | E6: =1/B6 -> 0.0040159368 | F6: =1/D6 -> 0.0040944307 | G6: =A6/(4*(10^-7)) -> 502142250 | H6: =ABS((G6*(E6-F6))/10000) -> 3.9415068 | I6: =A6/(1.2*(10^-7)) -> 1673807500 | J6: =(I6*(E6-0.000513))/10000 -> 586.3242 | L6: =(A6/(4*10^-7))*((1/D6)-(1/A6)) -> -444013.37 | M6: =(A6/(1.2*10^-7))*((1/B6)-(1/1949)) -> 5863102 | N6: =L6+M6 -> 5419088.6
A7: 181.7894 | B7: 216.5693 | C7: 230.409 | D7: 198.2799 | E7: =1/B7 -> 0.0046174596 | F7: =1/D7 -> 0.0050433756 | G7: =A7/(4*(10^-7)) -> 454473500 | H7: =ABS((G7*(E7-F7))/10000) -> 19.35675 | I7: =A7/(1.2*(10^-7)) -> 1514911667 | J7: =(I7*(E7-0.000513))/10000 -> 621.78938 | L7: =(A7/(4*10^-7))*((1/D7)-(1/A7)) -> -207919.46 | M7: =(A7/(1.2*10^-7))*((1/B7)-(1/1949)) -> 6217767.1 | N7: =L7+M7 -> 6009847.6
A8: 169.652 | B8: 201.1833 | C8: 214.9433 | D8: 161.8855 | E8: =1/B8 -> 0.0049705915 | F8: =1/D8 -> 0.0061772055 | G8: =A8/(4*(10^-7)) -> 424130000 | H8: =ABS((G8*(E8-F8))/10000) -> 51.17612 | I8: =A8/(1.2*(10^-7)) -> 1413766667 | J8: =(I8*(E8-0.000513))/10000 -> 630.19943 | L8: =(A8/(4*10^-7))*((1/D8)-(1/A8)) -> 119938.17 | M8: =(A8/(1.2*10^-7))*((1/B8)-(1/1949)) -> 6301876 | N8: =L8+M8 -> 6421814.2
A9: 158.5866 | B9: 192.7874 | C9: 204.9922 | D9: 154.5627 | E9: =1/B9 -> 0.005187061 | F9: =1/D9 -> 0.0064698663 | G9: =A9/(4*(10^-7)) -> 396466500 | H9: =ABS((G9*(E9-F9))/10000) -> 50.858933 | I9: =A9/(1.2*(10^-7)) -> 1321555000 | J9: =(I9*(E9-0.000513))/10000 -> 617.70287 | L9: =(A9/(4*10^-7))*((1/D9)-(1/A9)) -> 65085.237 | M9: =(A9/(1.2*10^-7))*((1/B9)-(1/1949)) -> 6176918.1 | N9: =L9+M9 -> 6242003.4
A10: 143.0686 | B10: 188.4116 | C10: 199.6382 | D10: 147.7557 | E10: =1/B10 -> 0.0053075288 | F10: =1/D10 -> 0.0067679284 | G10: =A10/(4*(10^-7)) -> 357671500 | H10: =ABS((G10*(E10-F10))/10000) -> 52.234331 | I10: =A10/(1.2*(10^-7)) -> 1192238333 | J10: =(I10*(E10-0.000513))/10000 -> 571.62211 | L10: =(A10/(4*10^-7))*((1/D10)-(1/A10)) -> -79304.893 | M10: =(A10/(1.2*10^-7))*((1/B10)-(1/1949)) -> 5716121.4 | N10: =L10+M10 -> 5636816.5
A11: 134.8949 | B11: 178.8564 | C11: 188.6397 | D11: 148.0392 | E11: =1/B11 -> 0.0055910775 | F11: =1/D11 -> 0.0067549676 | G11: =A11/(4*(10^-7)) -> 337237250 | H11: =ABS((G11*(E11-F11))/10000) -> 39.250709 | I11: =A11/(1.2*(10^-7)) -> 1124124167 | J11: =(I11*(E11-0.000513))/10000 -> 570.83897 | L11: =(A11/(4*10^-7))*((1/D11)-(1/A11)) -> -221973.3 | M11: =(A11/(1.2*10^-7))*((1/B11)-(1/1949)) -> 5708295.7 | N11: =L11+M11 -> 5486322.4
A12: 125.2556 | B12: 162.9519 | C12: 170.4498 | D12: 149.4117 | E12: =1/B12 -> 0.0061367802 | F12: =1/D12 -> 0.0066929163 | G12: =A12/(4*(10^-7)) -> 313139000 | H12: =ABS((G12*(E12-F12))/10000) -> 17.414788 | I12: =A12/(1.2*(10^-7)) -> 1043796667 | J12: =(I12*(E12-0.000513))/10000 -> 587.00831 | L12: =(A12/(4*10^-7))*((1/D12)-(1/A12)) -> -404186.89 | M12: =(A12/(1.2*10^-7))*((1/B12)-(1/1949)) -> 5869995.8 | N12: =L12+M12 -> 5465808.9
